Watching for file changes with StatReloader
Not Found: /
"GET / HTTP/1.1" 404 2461
"GET /users/ HTTP/1.1" 302 0
"GET /users/login/?next=/users/ HTTP/1.1" 200 1787
"GET /static/chipin/styles.css HTTP/1.1" 304 0
"GET /static/chipin/logo_90.jpg HTTP/1.1" 200 17515
"POST /users/login/ HTTP/1.1" 302 0
"GET /users/login/ HTTP/1.1" 200 1936
"GET /users/register/ HTTP/1.1" 200 2762
"GET /users/register/ HTTP/1.1" 200 2762
Internal Server Error: /users/register/
Traceback (most recent call last):
  File "C:\Users\melie\AppData\Local\Programs\Python\Python312\Lib\site-packages\django\core\handlers\exception.py", line 55, in inner
    response = get_response(request)
               ^^^^^^^^^^^^^^^^^^^^^
  File "C:\Users\melie\AppData\Local\Programs\Python\Python312\Lib\site-packages\django\core\handlers\base.py", line 197, in _get_response
    response = wrapped_callback(request, *callback_args, **callback_kwargs)
               ^^^^^^^^^^^^^^^^^^^^^^^^^^^^^^^^^^^^^^^^^^^^^^^^^^^^^^^^^^^^
  File "C:\Users\melie\ssa_project\users\views.py", line 83, in register
    if form.is_valid():
       ^^^^^^^^^^^^^^^
  File "C:\Users\melie\AppData\Local\Programs\Python\Python312\Lib\site-packages\django\forms\forms.py", line 197, in is_valid
    return self.is_bound and not self.errors
                                 ^^^^^^^^^^^
  File "C:\Users\melie\AppData\Local\Programs\Python\Python312\Lib\site-packages\django\forms\forms.py", line 192, in errors
    self.full_clean()
  File "C:\Users\melie\AppData\Local\Programs\Python\Python312\Lib\site-packages\django\forms\forms.py", line 325, in full_clean
    self._clean_fields()
  File "C:\Users\melie\AppData\Local\Programs\Python\Python312\Lib\site-packages\django\forms\forms.py", line 335, in _clean_fields
    value = getattr(self, "clean_%s" % name)()
            ^^^^^^^^^^^^^^^^^^^^^^^^^^^^^^^^^^
  File "C:\Users\melie\AppData\Local\Programs\Python\Python312\Lib\site-packages\django\contrib\auth\forms.py", line 268, in clean_username
    and self._meta.model.objects.filter(username__iexact=username).exists()
        ^^^^^^^^^^^^^^^^^^^^^^^^
  File "C:\Users\melie\AppData\Local\Programs\Python\Python312\Lib\site-packages\django\db\models\manager.py", line 196, in __get__
    raise AttributeError(
AttributeError: Manager isn't available; 'auth.User' has been swapped for 'users.CustomUser'
"POST /users/register/ HTTP/1.1" 500 89662
C:\Users\melie\ssa_project\users\forms.py changed, reloading.
Watching for file changes with StatReloader
C:\Users\melie\ssa_project\users\views.py changed, reloading.
Watching for file changes with StatReloader
C:\Users\melie\ssa_project\users\views.py changed, reloading.
Watching for file changes with StatReloader
Internal Server Error: /users/register/
Traceback (most recent call last):
  File "C:\Users\melie\AppData\Local\Programs\Python\Python312\Lib\site-packages\django\db\backends\utils.py", line 105, in _execute
    return self.cursor.execute(sql, params)
           ^^^^^^^^^^^^^^^^^^^^^^^^^^^^^^^^
  File "C:\Users\melie\AppData\Local\Programs\Python\Python312\Lib\site-packages\django\db\backends\sqlite3\base.py", line 354, in execute
    return super().execute(query, params)
           ^^^^^^^^^^^^^^^^^^^^^^^^^^^^^^
sqlite3.OperationalError: no such table: users_customuser

The above exception was the direct cause of the following exception:

Traceback (most recent call last):
  File "C:\Users\melie\AppData\Local\Programs\Python\Python312\Lib\site-packages\django\core\handlers\exception.py", line 55, in inner
    response = get_response(request)
               ^^^^^^^^^^^^^^^^^^^^^
  File "C:\Users\melie\AppData\Local\Programs\Python\Python312\Lib\site-packages\django\core\handlers\base.py", line 197, in _get_response
    response = wrapped_callback(request, *callback_args, **callback_kwargs)
               ^^^^^^^^^^^^^^^^^^^^^^^^^^^^^^^^^^^^^^^^^^^^^^^^^^^^^^^^^^^^
  File "C:\Users\melie\ssa_project\users\views.py", line 85, in register
    if form.is_valid():
       ^^^^^^^^^^^^^^^
  File "C:\Users\melie\AppData\Local\Programs\Python\Python312\Lib\site-packages\django\forms\forms.py", line 197, in is_valid
    return self.is_bound and not self.errors
                                 ^^^^^^^^^^^
  File "C:\Users\melie\AppData\Local\Programs\Python\Python312\Lib\site-packages\django\forms\forms.py", line 192, in errors
    self.full_clean()
  File "C:\Users\melie\AppData\Local\Programs\Python\Python312\Lib\site-packages\django\forms\forms.py", line 325, in full_clean
    self._clean_fields()
  File "C:\Users\melie\AppData\Local\Programs\Python\Python312\Lib\site-packages\django\forms\forms.py", line 335, in _clean_fields
    value = getattr(self, "clean_%s" % name)()
            ^^^^^^^^^^^^^^^^^^^^^^^^^^^^^^^^^^
  File "C:\Users\melie\AppData\Local\Programs\Python\Python312\Lib\site-packages\django\contrib\auth\forms.py", line 268, in clean_username
    and self._meta.model.objects.filter(username__iexact=username).exists()
        ^^^^^^^^^^^^^^^^^^^^^^^^^^^^^^^^^^^^^^^^^^^^^^^^^^^^^^^^^^^^^^^^^^^
  File "C:\Users\melie\AppData\Local\Programs\Python\Python312\Lib\site-packages\django\db\models\query.py", line 1288, in exists
    return self.query.has_results(using=self.db)
           ^^^^^^^^^^^^^^^^^^^^^^^^^^^^^^^^^^^^^
  File "C:\Users\melie\AppData\Local\Programs\Python\Python312\Lib\site-packages\django\db\models\sql\query.py", line 660, in has_results
    return compiler.has_results()
           ^^^^^^^^^^^^^^^^^^^^^^
  File "C:\Users\melie\AppData\Local\Programs\Python\Python312\Lib\site-packages\django\db\models\sql\compiler.py", line 1542, in has_results
    return bool(self.execute_sql(SINGLE))
                ^^^^^^^^^^^^^^^^^^^^^^^^
  File "C:\Users\melie\AppData\Local\Programs\Python\Python312\Lib\site-packages\django\db\models\sql\compiler.py", line 1574, in execute_sql
    cursor.execute(sql, params)
  File "C:\Users\melie\AppData\Local\Programs\Python\Python312\Lib\site-packages\django\db\backends\utils.py", line 122, in execute
    return super().execute(sql, params)
           ^^^^^^^^^^^^^^^^^^^^^^^^^^^^
  File "C:\Users\melie\AppData\Local\Programs\Python\Python312\Lib\site-packages\django\db\backends\utils.py", line 79, in execute
    return self._execute_with_wrappers(
           ^^^^^^^^^^^^^^^^^^^^^^^^^^^^
  File "C:\Users\melie\AppData\Local\Programs\Python\Python312\Lib\site-packages\django\db\backends\utils.py", line 92, in _execute_with_wrappers
    return executor(sql, params, many, context)
           ^^^^^^^^^^^^^^^^^^^^^^^^^^^^^^^^^^^^
  File "C:\Users\melie\AppData\Local\Programs\Python\Python312\Lib\site-packages\django\db\backends\utils.py", line 100, in _execute
    with self.db.wrap_database_errors:
  File "C:\Users\melie\AppData\Local\Programs\Python\Python312\Lib\site-packages\django\db\utils.py", line 91, in __exit__
    raise dj_exc_value.with_traceback(traceback) from exc_value
  File "C:\Users\melie\AppData\Local\Programs\Python\Python312\Lib\site-packages\django\db\backends\utils.py", line 105, in _execute
    return self.cursor.execute(sql, params)
           ^^^^^^^^^^^^^^^^^^^^^^^^^^^^^^^^
  File "C:\Users\melie\AppData\Local\Programs\Python\Python312\Lib\site-packages\django\db\backends\sqlite3\base.py", line 354, in execute
    return super().execute(query, params)
           ^^^^^^^^^^^^^^^^^^^^^^^^^^^^^^
django.db.utils.OperationalError: no such table: users_customuser
"POST /users/register/ HTTP/1.1" 500 146552
Watching for file changes with StatReloader
Internal Server Error: /users/register/
Traceback (most recent call last):
  File "C:\Users\melie\AppData\Local\Programs\Python\Python312\Lib\site-packages\django\db\backends\utils.py", line 105, in _execute
    return self.cursor.execute(sql, params)
           ^^^^^^^^^^^^^^^^^^^^^^^^^^^^^^^^
  File "C:\Users\melie\AppData\Local\Programs\Python\Python312\Lib\site-packages\django\db\backends\sqlite3\base.py", line 354, in execute
    return super().execute(query, params)
           ^^^^^^^^^^^^^^^^^^^^^^^^^^^^^^
sqlite3.OperationalError: no such table: users_customuser

The above exception was the direct cause of the following exception:

Traceback (most recent call last):
  File "C:\Users\melie\AppData\Local\Programs\Python\Python312\Lib\site-packages\django\core\handlers\exception.py", line 55, in inner
    response = get_response(request)
               ^^^^^^^^^^^^^^^^^^^^^
  File "C:\Users\melie\AppData\Local\Programs\Python\Python312\Lib\site-packages\django\core\handlers\base.py", line 197, in _get_response
    response = wrapped_callback(request, *callback_args, **callback_kwargs)
               ^^^^^^^^^^^^^^^^^^^^^^^^^^^^^^^^^^^^^^^^^^^^^^^^^^^^^^^^^^^^
  File "C:\Users\melie\ssa_project\users\views.py", line 85, in register
    if form.is_valid():
       ^^^^^^^^^^^^^^^
  File "C:\Users\melie\AppData\Local\Programs\Python\Python312\Lib\site-packages\django\forms\forms.py", line 197, in is_valid
    return self.is_bound and not self.errors
                                 ^^^^^^^^^^^
  File "C:\Users\melie\AppData\Local\Programs\Python\Python312\Lib\site-packages\django\forms\forms.py", line 192, in errors
    self.full_clean()
  File "C:\Users\melie\AppData\Local\Programs\Python\Python312\Lib\site-packages\django\forms\forms.py", line 325, in full_clean
    self._clean_fields()
  File "C:\Users\melie\AppData\Local\Programs\Python\Python312\Lib\site-packages\django\forms\forms.py", line 335, in _clean_fields
    value = getattr(self, "clean_%s" % name)()
            ^^^^^^^^^^^^^^^^^^^^^^^^^^^^^^^^^^
  File "C:\Users\melie\AppData\Local\Programs\Python\Python312\Lib\site-packages\django\contrib\auth\forms.py", line 268, in clean_username
    and self._meta.model.objects.filter(username__iexact=username).exists()
        ^^^^^^^^^^^^^^^^^^^^^^^^^^^^^^^^^^^^^^^^^^^^^^^^^^^^^^^^^^^^^^^^^^^
  File "C:\Users\melie\AppData\Local\Programs\Python\Python312\Lib\site-packages\django\db\models\query.py", line 1288, in exists
    return self.query.has_results(using=self.db)
           ^^^^^^^^^^^^^^^^^^^^^^^^^^^^^^^^^^^^^
  File "C:\Users\melie\AppData\Local\Programs\Python\Python312\Lib\site-packages\django\db\models\sql\query.py", line 660, in has_results
    return compiler.has_results()
           ^^^^^^^^^^^^^^^^^^^^^^
  File "C:\Users\melie\AppData\Local\Programs\Python\Python312\Lib\site-packages\django\db\models\sql\compiler.py", line 1542, in has_results
    return bool(self.execute_sql(SINGLE))
                ^^^^^^^^^^^^^^^^^^^^^^^^
  File "C:\Users\melie\AppData\Local\Programs\Python\Python312\Lib\site-packages\django\db\models\sql\compiler.py", line 1574, in execute_sql
    cursor.execute(sql, params)
  File "C:\Users\melie\AppData\Local\Programs\Python\Python312\Lib\site-packages\django\db\backends\utils.py", line 122, in execute
    return super().execute(sql, params)
           ^^^^^^^^^^^^^^^^^^^^^^^^^^^^
  File "C:\Users\melie\AppData\Local\Programs\Python\Python312\Lib\site-packages\django\db\backends\utils.py", line 79, in execute
    return self._execute_with_wrappers(
           ^^^^^^^^^^^^^^^^^^^^^^^^^^^^
  File "C:\Users\melie\AppData\Local\Programs\Python\Python312\Lib\site-packages\django\db\backends\utils.py", line 92, in _execute_with_wrappers
    return executor(sql, params, many, context)
           ^^^^^^^^^^^^^^^^^^^^^^^^^^^^^^^^^^^^
  File "C:\Users\melie\AppData\Local\Programs\Python\Python312\Lib\site-packages\django\db\backends\utils.py", line 100, in _execute
    with self.db.wrap_database_errors:
  File "C:\Users\melie\AppData\Local\Programs\Python\Python312\Lib\site-packages\django\db\utils.py", line 91, in __exit__
    raise dj_exc_value.with_traceback(traceback) from exc_value
  File "C:\Users\melie\AppData\Local\Programs\Python\Python312\Lib\site-packages\django\db\backends\utils.py", line 105, in _execute
    return self.cursor.execute(sql, params)
           ^^^^^^^^^^^^^^^^^^^^^^^^^^^^^^^^
  File "C:\Users\melie\AppData\Local\Programs\Python\Python312\Lib\site-packages\django\db\backends\sqlite3\base.py", line 354, in execute
    return super().execute(query, params)
           ^^^^^^^^^^^^^^^^^^^^^^^^^^^^^^
django.db.utils.OperationalError: no such table: users_customuser
"POST /users/register/ HTTP/1.1" 500 146552
C:\Users\melie\ssa_project\users\admin.py changed, reloading.
Watching for file changes with StatReloader
C:\Users\melie\ssa_project\users\admin.py changed, reloading.
Watching for file changes with StatReloader
Internal Server Error: /users/register/
Traceback (most recent call last):
  File "C:\Users\melie\AppData\Local\Programs\Python\Python312\Lib\site-packages\django\db\backends\utils.py", line 105, in _execute
    return self.cursor.execute(sql, params)
           ^^^^^^^^^^^^^^^^^^^^^^^^^^^^^^^^
  File "C:\Users\melie\AppData\Local\Programs\Python\Python312\Lib\site-packages\django\db\backends\sqlite3\base.py", line 354, in execute
    return super().execute(query, params)
           ^^^^^^^^^^^^^^^^^^^^^^^^^^^^^^
sqlite3.OperationalError: no such table: users_customuser

The above exception was the direct cause of the following exception:

Traceback (most recent call last):
  File "C:\Users\melie\AppData\Local\Programs\Python\Python312\Lib\site-packages\django\core\handlers\exception.py", line 55, in inner
    response = get_response(request)
               ^^^^^^^^^^^^^^^^^^^^^
  File "C:\Users\melie\AppData\Local\Programs\Python\Python312\Lib\site-packages\django\core\handlers\base.py", line 197, in _get_response
    response = wrapped_callback(request, *callback_args, **callback_kwargs)
               ^^^^^^^^^^^^^^^^^^^^^^^^^^^^^^^^^^^^^^^^^^^^^^^^^^^^^^^^^^^^
  File "C:\Users\melie\ssa_project\users\views.py", line 85, in register
    if form.is_valid():
       ^^^^^^^^^^^^^^^
  File "C:\Users\melie\AppData\Local\Programs\Python\Python312\Lib\site-packages\django\forms\forms.py", line 197, in is_valid
    return self.is_bound and not self.errors
                                 ^^^^^^^^^^^
  File "C:\Users\melie\AppData\Local\Programs\Python\Python312\Lib\site-packages\django\forms\forms.py", line 192, in errors
    self.full_clean()
  File "C:\Users\melie\AppData\Local\Programs\Python\Python312\Lib\site-packages\django\forms\forms.py", line 325, in full_clean
    self._clean_fields()
  File "C:\Users\melie\AppData\Local\Programs\Python\Python312\Lib\site-packages\django\forms\forms.py", line 335, in _clean_fields
    value = getattr(self, "clean_%s" % name)()
            ^^^^^^^^^^^^^^^^^^^^^^^^^^^^^^^^^^
  File "C:\Users\melie\AppData\Local\Programs\Python\Python312\Lib\site-packages\django\contrib\auth\forms.py", line 268, in clean_username
    and self._meta.model.objects.filter(username__iexact=username).exists()
        ^^^^^^^^^^^^^^^^^^^^^^^^^^^^^^^^^^^^^^^^^^^^^^^^^^^^^^^^^^^^^^^^^^^
  File "C:\Users\melie\AppData\Local\Programs\Python\Python312\Lib\site-packages\django\db\models\query.py", line 1288, in exists
    return self.query.has_results(using=self.db)
           ^^^^^^^^^^^^^^^^^^^^^^^^^^^^^^^^^^^^^
  File "C:\Users\melie\AppData\Local\Programs\Python\Python312\Lib\site-packages\django\db\models\sql\query.py", line 660, in has_results
    return compiler.has_results()
           ^^^^^^^^^^^^^^^^^^^^^^
  File "C:\Users\melie\AppData\Local\Programs\Python\Python312\Lib\site-packages\django\db\models\sql\compiler.py", line 1542, in has_results
    return bool(self.execute_sql(SINGLE))
                ^^^^^^^^^^^^^^^^^^^^^^^^
  File "C:\Users\melie\AppData\Local\Programs\Python\Python312\Lib\site-packages\django\db\models\sql\compiler.py", line 1574, in execute_sql
    cursor.execute(sql, params)
  File "C:\Users\melie\AppData\Local\Programs\Python\Python312\Lib\site-packages\django\db\backends\utils.py", line 122, in execute
    return super().execute(sql, params)
           ^^^^^^^^^^^^^^^^^^^^^^^^^^^^
  File "C:\Users\melie\AppData\Local\Programs\Python\Python312\Lib\site-packages\django\db\backends\utils.py", line 79, in execute
    return self._execute_with_wrappers(
           ^^^^^^^^^^^^^^^^^^^^^^^^^^^^
  File "C:\Users\melie\AppData\Local\Programs\Python\Python312\Lib\site-packages\django\db\backends\utils.py", line 92, in _execute_with_wrappers
    return executor(sql, params, many, context)
           ^^^^^^^^^^^^^^^^^^^^^^^^^^^^^^^^^^^^
  File "C:\Users\melie\AppData\Local\Programs\Python\Python312\Lib\site-packages\django\db\backends\utils.py", line 100, in _execute
    with self.db.wrap_database_errors:
  File "C:\Users\melie\AppData\Local\Programs\Python\Python312\Lib\site-packages\django\db\utils.py", line 91, in __exit__
    raise dj_exc_value.with_traceback(traceback) from exc_value
  File "C:\Users\melie\AppData\Local\Programs\Python\Python312\Lib\site-packages\django\db\backends\utils.py", line 105, in _execute
    return self.cursor.execute(sql, params)
           ^^^^^^^^^^^^^^^^^^^^^^^^^^^^^^^^
  File "C:\Users\melie\AppData\Local\Programs\Python\Python312\Lib\site-packages\django\db\backends\sqlite3\base.py", line 354, in execute
    return super().execute(query, params)
           ^^^^^^^^^^^^^^^^^^^^^^^^^^^^^^
django.db.utils.OperationalError: no such table: users_customuser
"POST /users/register/ HTTP/1.1" 500 146552
Watching for file changes with StatReloader
Watching for file changes with StatReloader
Internal Server Error: /users/register/
Traceback (most recent call last):
  File "C:\Users\melie\AppData\Local\Programs\Python\Python312\Lib\site-packages\django\db\backends\utils.py", line 105, in _execute
    return self.cursor.execute(sql, params)
           ^^^^^^^^^^^^^^^^^^^^^^^^^^^^^^^^
  File "C:\Users\melie\AppData\Local\Programs\Python\Python312\Lib\site-packages\django\db\backends\sqlite3\base.py", line 354, in execute
    return super().execute(query, params)
           ^^^^^^^^^^^^^^^^^^^^^^^^^^^^^^
sqlite3.OperationalError: no such table: users_customuser

The above exception was the direct cause of the following exception:

Traceback (most recent call last):
  File "C:\Users\melie\AppData\Local\Programs\Python\Python312\Lib\site-packages\django\core\handlers\exception.py", line 55, in inner
    response = get_response(request)
               ^^^^^^^^^^^^^^^^^^^^^
  File "C:\Users\melie\AppData\Local\Programs\Python\Python312\Lib\site-packages\django\core\handlers\base.py", line 197, in _get_response
    response = wrapped_callback(request, *callback_args, **callback_kwargs)
               ^^^^^^^^^^^^^^^^^^^^^^^^^^^^^^^^^^^^^^^^^^^^^^^^^^^^^^^^^^^^
  File "C:\Users\melie\ssa_project\users\views.py", line 85, in register
    if form.is_valid():
       ^^^^^^^^^^^^^^^
  File "C:\Users\melie\AppData\Local\Programs\Python\Python312\Lib\site-packages\django\forms\forms.py", line 197, in is_valid
    return self.is_bound and not self.errors
                                 ^^^^^^^^^^^
  File "C:\Users\melie\AppData\Local\Programs\Python\Python312\Lib\site-packages\django\forms\forms.py", line 192, in errors
    self.full_clean()
  File "C:\Users\melie\AppData\Local\Programs\Python\Python312\Lib\site-packages\django\forms\forms.py", line 325, in full_clean
    self._clean_fields()
  File "C:\Users\melie\AppData\Local\Programs\Python\Python312\Lib\site-packages\django\forms\forms.py", line 335, in _clean_fields
    value = getattr(self, "clean_%s" % name)()
            ^^^^^^^^^^^^^^^^^^^^^^^^^^^^^^^^^^
  File "C:\Users\melie\AppData\Local\Programs\Python\Python312\Lib\site-packages\django\contrib\auth\forms.py", line 268, in clean_username
    and self._meta.model.objects.filter(username__iexact=username).exists()
        ^^^^^^^^^^^^^^^^^^^^^^^^^^^^^^^^^^^^^^^^^^^^^^^^^^^^^^^^^^^^^^^^^^^
  File "C:\Users\melie\AppData\Local\Programs\Python\Python312\Lib\site-packages\django\db\models\query.py", line 1288, in exists
    return self.query.has_results(using=self.db)
           ^^^^^^^^^^^^^^^^^^^^^^^^^^^^^^^^^^^^^
  File "C:\Users\melie\AppData\Local\Programs\Python\Python312\Lib\site-packages\django\db\models\sql\query.py", line 660, in has_results
    return compiler.has_results()
           ^^^^^^^^^^^^^^^^^^^^^^
  File "C:\Users\melie\AppData\Local\Programs\Python\Python312\Lib\site-packages\django\db\models\sql\compiler.py", line 1542, in has_results
    return bool(self.execute_sql(SINGLE))
                ^^^^^^^^^^^^^^^^^^^^^^^^
  File "C:\Users\melie\AppData\Local\Programs\Python\Python312\Lib\site-packages\django\db\models\sql\compiler.py", line 1574, in execute_sql
    cursor.execute(sql, params)
  File "C:\Users\melie\AppData\Local\Programs\Python\Python312\Lib\site-packages\django\db\backends\utils.py", line 122, in execute
    return super().execute(sql, params)
           ^^^^^^^^^^^^^^^^^^^^^^^^^^^^
  File "C:\Users\melie\AppData\Local\Programs\Python\Python312\Lib\site-packages\django\db\backends\utils.py", line 79, in execute
    return self._execute_with_wrappers(
           ^^^^^^^^^^^^^^^^^^^^^^^^^^^^
  File "C:\Users\melie\AppData\Local\Programs\Python\Python312\Lib\site-packages\django\db\backends\utils.py", line 92, in _execute_with_wrappers
    return executor(sql, params, many, context)
           ^^^^^^^^^^^^^^^^^^^^^^^^^^^^^^^^^^^^
  File "C:\Users\melie\AppData\Local\Programs\Python\Python312\Lib\site-packages\django\db\backends\utils.py", line 100, in _execute
    with self.db.wrap_database_errors:
  File "C:\Users\melie\AppData\Local\Programs\Python\Python312\Lib\site-packages\django\db\utils.py", line 91, in __exit__
    raise dj_exc_value.with_traceback(traceback) from exc_value
  File "C:\Users\melie\AppData\Local\Programs\Python\Python312\Lib\site-packages\django\db\backends\utils.py", line 105, in _execute
    return self.cursor.execute(sql, params)
           ^^^^^^^^^^^^^^^^^^^^^^^^^^^^^^^^
  File "C:\Users\melie\AppData\Local\Programs\Python\Python312\Lib\site-packages\django\db\backends\sqlite3\base.py", line 354, in execute
    return super().execute(query, params)
           ^^^^^^^^^^^^^^^^^^^^^^^^^^^^^^
django.db.utils.OperationalError: no such table: users_customuser
"POST /users/register/ HTTP/1.1" 500 146552
Watching for file changes with StatReloader
Internal Server Error: /users/register/
Traceback (most recent call last):
  File "C:\Users\melie\AppData\Local\Programs\Python\Python312\Lib\site-packages\django\core\handlers\exception.py", line 55, in inner
    response = get_response(request)
               ^^^^^^^^^^^^^^^^^^^^^
  File "C:\Users\melie\AppData\Local\Programs\Python\Python312\Lib\site-packages\django\core\handlers\base.py", line 197, in _get_response
    response = wrapped_callback(request, *callback_args, **callback_kwargs)
               ^^^^^^^^^^^^^^^^^^^^^^^^^^^^^^^^^^^^^^^^^^^^^^^^^^^^^^^^^^^^
  File "C:\Users\melie\ssa_project\users\views.py", line 86, in register
    form.save()
  File "C:\Users\melie\ssa_project\users\forms.py", line 34, in save
    profile = user.profile
              ^^^^^^^^^^^^
  File "C:\Users\melie\AppData\Local\Programs\Python\Python312\Lib\site-packages\django\db\models\fields\related_descriptors.py", line 531, in __get__
    raise self.RelatedObjectDoesNotExist(
users.models.CustomUser.profile.RelatedObjectDoesNotExist: CustomUser has no profile.
"POST /users/register/ HTTP/1.1" 500 74394
C:\Users\melie\ssa_project\users\models.py changed, reloading.
Watching for file changes with StatReloader
"POST /users/register/ HTTP/1.1" 200 3054
"GET /static/chipin/styles.css HTTP/1.1" 304 0
"POST /users/register/ HTTP/1.1" 200 3054
Watching for file changes with StatReloader
"POST /users/register/ HTTP/1.1" 302 0
"GET /users/login/ HTTP/1.1" 200 1942
"POST /users/login/ HTTP/1.1" 302 0
"GET /users/login/ HTTP/1.1" 200 1936
"POST /users/login/ HTTP/1.1" 302 0
"GET /users/login/ HTTP/1.1" 200 1936
"GET /users/login/ HTTP/1.1" 200 1787
"POST /users/login/ HTTP/1.1" 200 1919
"POST /users/login/ HTTP/1.1" 200 1919
"GET /users/login/ HTTP/1.1" 200 1787
"POST /users/login/ HTTP/1.1" 302 0
"GET /users/login/ HTTP/1.1" 200 1936
"GET /users/login/ HTTP/1.1" 200 1787
"GET /users/login/ HTTP/1.1" 200 1787
"POST /users/login/ HTTP/1.1" 302 0
"GET /users/ HTTP/1.1" 200 972
"GET /chipin/ HTTP/1.1" 200 981
