Watching for file changes with StatReloader
Not Found: /
"GET / HTTP/1.1" 404 2461
"GET /users/ HTTP/1.1" 302 0
"GET /users/login/?next=/users/ HTTP/1.1" 200 1787
"GET /static/chipin/styles.css HTTP/1.1" 304 0
"GET /static/chipin/logo_90.jpg HTTP/1.1" 200 17515
"POST /users/login/ HTTP/1.1" 302 0
"GET /users/login/ HTTP/1.1" 200 1936
"GET /users/register/ HTTP/1.1" 200 2762
"GET /users/register/ HTTP/1.1" 200 2762
Internal Server Error: /users/register/
Traceback (most recent call last):
  File "C:\Users\melie\AppData\Local\Programs\Python\Python312\Lib\site-packages\django\core\handlers\exception.py", line 55, in inner
    response = get_response(request)
               ^^^^^^^^^^^^^^^^^^^^^
  File "C:\Users\melie\AppData\Local\Programs\Python\Python312\Lib\site-packages\django\core\handlers\base.py", line 197, in _get_response
    response = wrapped_callback(request, *callback_args, **callback_kwargs)
               ^^^^^^^^^^^^^^^^^^^^^^^^^^^^^^^^^^^^^^^^^^^^^^^^^^^^^^^^^^^^
  File "C:\Users\melie\ssa_project\users\views.py", line 83, in register
    if form.is_valid():
       ^^^^^^^^^^^^^^^
  File "C:\Users\melie\AppData\Local\Programs\Python\Python312\Lib\site-packages\django\forms\forms.py", line 197, in is_valid
    return self.is_bound and not self.errors
                                 ^^^^^^^^^^^
  File "C:\Users\melie\AppData\Local\Programs\Python\Python312\Lib\site-packages\django\forms\forms.py", line 192, in errors
    self.full_clean()
  File "C:\Users\melie\AppData\Local\Programs\Python\Python312\Lib\site-packages\django\forms\forms.py", line 325, in full_clean
    self._clean_fields()
  File "C:\Users\melie\AppData\Local\Programs\Python\Python312\Lib\site-packages\django\forms\forms.py", line 335, in _clean_fields
    value = getattr(self, "clean_%s" % name)()
            ^^^^^^^^^^^^^^^^^^^^^^^^^^^^^^^^^^
  File "C:\Users\melie\AppData\Local\Programs\Python\Python312\Lib\site-packages\django\contrib\auth\forms.py", line 268, in clean_username
    and self._meta.model.objects.filter(username__iexact=username).exists()
        ^^^^^^^^^^^^^^^^^^^^^^^^
  File "C:\Users\melie\AppData\Local\Programs\Python\Python312\Lib\site-packages\django\db\models\manager.py", line 196, in __get__
    raise AttributeError(
AttributeError: Manager isn't available; 'auth.User' has been swapped for 'users.CustomUser'
"POST /users/register/ HTTP/1.1" 500 89662
C:\Users\melie\ssa_project\users\forms.py changed, reloading.
Watching for file changes with StatReloader
C:\Users\melie\ssa_project\users\views.py changed, reloading.
Watching for file changes with StatReloader
C:\Users\melie\ssa_project\users\views.py changed, reloading.
Watching for file changes with StatReloader
Internal Server Error: /users/register/
Traceback (most recent call last):
  File "C:\Users\melie\AppData\Local\Programs\Python\Python312\Lib\site-packages\django\db\backends\utils.py", line 105, in _execute
    return self.cursor.execute(sql, params)
           ^^^^^^^^^^^^^^^^^^^^^^^^^^^^^^^^
  File "C:\Users\melie\AppData\Local\Programs\Python\Python312\Lib\site-packages\django\db\backends\sqlite3\base.py", line 354, in execute
    return super().execute(query, params)
           ^^^^^^^^^^^^^^^^^^^^^^^^^^^^^^
sqlite3.OperationalError: no such table: users_customuser

The above exception was the direct cause of the following exception:

Traceback (most recent call last):
  File "C:\Users\melie\AppData\Local\Programs\Python\Python312\Lib\site-packages\django\core\handlers\exception.py", line 55, in inner
    response = get_response(request)
               ^^^^^^^^^^^^^^^^^^^^^
  File "C:\Users\melie\AppData\Local\Programs\Python\Python312\Lib\site-packages\django\core\handlers\base.py", line 197, in _get_response
    response = wrapped_callback(request, *callback_args, **callback_kwargs)
               ^^^^^^^^^^^^^^^^^^^^^^^^^^^^^^^^^^^^^^^^^^^^^^^^^^^^^^^^^^^^
  File "C:\Users\melie\ssa_project\users\views.py", line 85, in register
    if form.is_valid():
       ^^^^^^^^^^^^^^^
  File "C:\Users\melie\AppData\Local\Programs\Python\Python312\Lib\site-packages\django\forms\forms.py", line 197, in is_valid
    return self.is_bound and not self.errors
                                 ^^^^^^^^^^^
  File "C:\Users\melie\AppData\Local\Programs\Python\Python312\Lib\site-packages\django\forms\forms.py", line 192, in errors
    self.full_clean()
  File "C:\Users\melie\AppData\Local\Programs\Python\Python312\Lib\site-packages\django\forms\forms.py", line 325, in full_clean
    self._clean_fields()
  File "C:\Users\melie\AppData\Local\Programs\Python\Python312\Lib\site-packages\django\forms\forms.py", line 335, in _clean_fields
    value = getattr(self, "clean_%s" % name)()
            ^^^^^^^^^^^^^^^^^^^^^^^^^^^^^^^^^^
  File "C:\Users\melie\AppData\Local\Programs\Python\Python312\Lib\site-packages\django\contrib\auth\forms.py", line 268, in clean_username
    and self._meta.model.objects.filter(username__iexact=username).exists()
        ^^^^^^^^^^^^^^^^^^^^^^^^^^^^^^^^^^^^^^^^^^^^^^^^^^^^^^^^^^^^^^^^^^^
  File "C:\Users\melie\AppData\Local\Programs\Python\Python312\Lib\site-packages\django\db\models\query.py", line 1288, in exists
    return self.query.has_results(using=self.db)
           ^^^^^^^^^^^^^^^^^^^^^^^^^^^^^^^^^^^^^
  File "C:\Users\melie\AppData\Local\Programs\Python\Python312\Lib\site-packages\django\db\models\sql\query.py", line 660, in has_results
    return compiler.has_results()
           ^^^^^^^^^^^^^^^^^^^^^^
  File "C:\Users\melie\AppData\Local\Programs\Python\Python312\Lib\site-packages\django\db\models\sql\compiler.py", line 1542, in has_results
    return bool(self.execute_sql(SINGLE))
                ^^^^^^^^^^^^^^^^^^^^^^^^
  File "C:\Users\melie\AppData\Local\Programs\Python\Python312\Lib\site-packages\django\db\models\sql\compiler.py", line 1574, in execute_sql
    cursor.execute(sql, params)
  File "C:\Users\melie\AppData\Local\Programs\Python\Python312\Lib\site-packages\django\db\backends\utils.py", line 122, in execute
    return super().execute(sql, params)
           ^^^^^^^^^^^^^^^^^^^^^^^^^^^^
  File "C:\Users\melie\AppData\Local\Programs\Python\Python312\Lib\site-packages\django\db\backends\utils.py", line 79, in execute
    return self._execute_with_wrappers(
           ^^^^^^^^^^^^^^^^^^^^^^^^^^^^
  File "C:\Users\melie\AppData\Local\Programs\Python\Python312\Lib\site-packages\django\db\backends\utils.py", line 92, in _execute_with_wrappers
    return executor(sql, params, many, context)
           ^^^^^^^^^^^^^^^^^^^^^^^^^^^^^^^^^^^^
  File "C:\Users\melie\AppData\Local\Programs\Python\Python312\Lib\site-packages\django\db\backends\utils.py", line 100, in _execute
    with self.db.wrap_database_errors:
  File "C:\Users\melie\AppData\Local\Programs\Python\Python312\Lib\site-packages\django\db\utils.py", line 91, in __exit__
    raise dj_exc_value.with_traceback(traceback) from exc_value
  File "C:\Users\melie\AppData\Local\Programs\Python\Python312\Lib\site-packages\django\db\backends\utils.py", line 105, in _execute
    return self.cursor.execute(sql, params)
           ^^^^^^^^^^^^^^^^^^^^^^^^^^^^^^^^
  File "C:\Users\melie\AppData\Local\Programs\Python\Python312\Lib\site-packages\django\db\backends\sqlite3\base.py", line 354, in execute
    return super().execute(query, params)
           ^^^^^^^^^^^^^^^^^^^^^^^^^^^^^^
django.db.utils.OperationalError: no such table: users_customuser
"POST /users/register/ HTTP/1.1" 500 146552
Watching for file changes with StatReloader
Internal Server Error: /users/register/
Traceback (most recent call last):
  File "C:\Users\melie\AppData\Local\Programs\Python\Python312\Lib\site-packages\django\db\backends\utils.py", line 105, in _execute
    return self.cursor.execute(sql, params)
           ^^^^^^^^^^^^^^^^^^^^^^^^^^^^^^^^
  File "C:\Users\melie\AppData\Local\Programs\Python\Python312\Lib\site-packages\django\db\backends\sqlite3\base.py", line 354, in execute
    return super().execute(query, params)
           ^^^^^^^^^^^^^^^^^^^^^^^^^^^^^^
sqlite3.OperationalError: no such table: users_customuser

The above exception was the direct cause of the following exception:

Traceback (most recent call last):
  File "C:\Users\melie\AppData\Local\Programs\Python\Python312\Lib\site-packages\django\core\handlers\exception.py", line 55, in inner
    response = get_response(request)
               ^^^^^^^^^^^^^^^^^^^^^
  File "C:\Users\melie\AppData\Local\Programs\Python\Python312\Lib\site-packages\django\core\handlers\base.py", line 197, in _get_response
    response = wrapped_callback(request, *callback_args, **callback_kwargs)
               ^^^^^^^^^^^^^^^^^^^^^^^^^^^^^^^^^^^^^^^^^^^^^^^^^^^^^^^^^^^^
  File "C:\Users\melie\ssa_project\users\views.py", line 85, in register
    if form.is_valid():
       ^^^^^^^^^^^^^^^
  File "C:\Users\melie\AppData\Local\Programs\Python\Python312\Lib\site-packages\django\forms\forms.py", line 197, in is_valid
    return self.is_bound and not self.errors
                                 ^^^^^^^^^^^
  File "C:\Users\melie\AppData\Local\Programs\Python\Python312\Lib\site-packages\django\forms\forms.py", line 192, in errors
    self.full_clean()
  File "C:\Users\melie\AppData\Local\Programs\Python\Python312\Lib\site-packages\django\forms\forms.py", line 325, in full_clean
    self._clean_fields()
  File "C:\Users\melie\AppData\Local\Programs\Python\Python312\Lib\site-packages\django\forms\forms.py", line 335, in _clean_fields
    value = getattr(self, "clean_%s" % name)()
            ^^^^^^^^^^^^^^^^^^^^^^^^^^^^^^^^^^
  File "C:\Users\melie\AppData\Local\Programs\Python\Python312\Lib\site-packages\django\contrib\auth\forms.py", line 268, in clean_username
    and self._meta.model.objects.filter(username__iexact=username).exists()
        ^^^^^^^^^^^^^^^^^^^^^^^^^^^^^^^^^^^^^^^^^^^^^^^^^^^^^^^^^^^^^^^^^^^
  File "C:\Users\melie\AppData\Local\Programs\Python\Python312\Lib\site-packages\django\db\models\query.py", line 1288, in exists
    return self.query.has_results(using=self.db)
           ^^^^^^^^^^^^^^^^^^^^^^^^^^^^^^^^^^^^^
  File "C:\Users\melie\AppData\Local\Programs\Python\Python312\Lib\site-packages\django\db\models\sql\query.py", line 660, in has_results
    return compiler.has_results()
           ^^^^^^^^^^^^^^^^^^^^^^
  File "C:\Users\melie\AppData\Local\Programs\Python\Python312\Lib\site-packages\django\db\models\sql\compiler.py", line 1542, in has_results
    return bool(self.execute_sql(SINGLE))
                ^^^^^^^^^^^^^^^^^^^^^^^^
  File "C:\Users\melie\AppData\Local\Programs\Python\Python312\Lib\site-packages\django\db\models\sql\compiler.py", line 1574, in execute_sql
    cursor.execute(sql, params)
  File "C:\Users\melie\AppData\Local\Programs\Python\Python312\Lib\site-packages\django\db\backends\utils.py", line 122, in execute
    return super().execute(sql, params)
           ^^^^^^^^^^^^^^^^^^^^^^^^^^^^
  File "C:\Users\melie\AppData\Local\Programs\Python\Python312\Lib\site-packages\django\db\backends\utils.py", line 79, in execute
    return self._execute_with_wrappers(
           ^^^^^^^^^^^^^^^^^^^^^^^^^^^^
  File "C:\Users\melie\AppData\Local\Programs\Python\Python312\Lib\site-packages\django\db\backends\utils.py", line 92, in _execute_with_wrappers
    return executor(sql, params, many, context)
           ^^^^^^^^^^^^^^^^^^^^^^^^^^^^^^^^^^^^
  File "C:\Users\melie\AppData\Local\Programs\Python\Python312\Lib\site-packages\django\db\backends\utils.py", line 100, in _execute
    with self.db.wrap_database_errors:
  File "C:\Users\melie\AppData\Local\Programs\Python\Python312\Lib\site-packages\django\db\utils.py", line 91, in __exit__
    raise dj_exc_value.with_traceback(traceback) from exc_value
  File "C:\Users\melie\AppData\Local\Programs\Python\Python312\Lib\site-packages\django\db\backends\utils.py", line 105, in _execute
    return self.cursor.execute(sql, params)
           ^^^^^^^^^^^^^^^^^^^^^^^^^^^^^^^^
  File "C:\Users\melie\AppData\Local\Programs\Python\Python312\Lib\site-packages\django\db\backends\sqlite3\base.py", line 354, in execute
    return super().execute(query, params)
           ^^^^^^^^^^^^^^^^^^^^^^^^^^^^^^
django.db.utils.OperationalError: no such table: users_customuser
"POST /users/register/ HTTP/1.1" 500 146552
C:\Users\melie\ssa_project\users\admin.py changed, reloading.
Watching for file changes with StatReloader
C:\Users\melie\ssa_project\users\admin.py changed, reloading.
Watching for file changes with StatReloader
Internal Server Error: /users/register/
Traceback (most recent call last):
  File "C:\Users\melie\AppData\Local\Programs\Python\Python312\Lib\site-packages\django\db\backends\utils.py", line 105, in _execute
    return self.cursor.execute(sql, params)
           ^^^^^^^^^^^^^^^^^^^^^^^^^^^^^^^^
  File "C:\Users\melie\AppData\Local\Programs\Python\Python312\Lib\site-packages\django\db\backends\sqlite3\base.py", line 354, in execute
    return super().execute(query, params)
           ^^^^^^^^^^^^^^^^^^^^^^^^^^^^^^
sqlite3.OperationalError: no such table: users_customuser

The above exception was the direct cause of the following exception:

Traceback (most recent call last):
  File "C:\Users\melie\AppData\Local\Programs\Python\Python312\Lib\site-packages\django\core\handlers\exception.py", line 55, in inner
    response = get_response(request)
               ^^^^^^^^^^^^^^^^^^^^^
  File "C:\Users\melie\AppData\Local\Programs\Python\Python312\Lib\site-packages\django\core\handlers\base.py", line 197, in _get_response
    response = wrapped_callback(request, *callback_args, **callback_kwargs)
               ^^^^^^^^^^^^^^^^^^^^^^^^^^^^^^^^^^^^^^^^^^^^^^^^^^^^^^^^^^^^
  File "C:\Users\melie\ssa_project\users\views.py", line 85, in register
    if form.is_valid():
       ^^^^^^^^^^^^^^^
  File "C:\Users\melie\AppData\Local\Programs\Python\Python312\Lib\site-packages\django\forms\forms.py", line 197, in is_valid
    return self.is_bound and not self.errors
                                 ^^^^^^^^^^^
  File "C:\Users\melie\AppData\Local\Programs\Python\Python312\Lib\site-packages\django\forms\forms.py", line 192, in errors
    self.full_clean()
  File "C:\Users\melie\AppData\Local\Programs\Python\Python312\Lib\site-packages\django\forms\forms.py", line 325, in full_clean
    self._clean_fields()
  File "C:\Users\melie\AppData\Local\Programs\Python\Python312\Lib\site-packages\django\forms\forms.py", line 335, in _clean_fields
    value = getattr(self, "clean_%s" % name)()
            ^^^^^^^^^^^^^^^^^^^^^^^^^^^^^^^^^^
  File "C:\Users\melie\AppData\Local\Programs\Python\Python312\Lib\site-packages\django\contrib\auth\forms.py", line 268, in clean_username
    and self._meta.model.objects.filter(username__iexact=username).exists()
        ^^^^^^^^^^^^^^^^^^^^^^^^^^^^^^^^^^^^^^^^^^^^^^^^^^^^^^^^^^^^^^^^^^^
  File "C:\Users\melie\AppData\Local\Programs\Python\Python312\Lib\site-packages\django\db\models\query.py", line 1288, in exists
    return self.query.has_results(using=self.db)
           ^^^^^^^^^^^^^^^^^^^^^^^^^^^^^^^^^^^^^
  File "C:\Users\melie\AppData\Local\Programs\Python\Python312\Lib\site-packages\django\db\models\sql\query.py", line 660, in has_results
    return compiler.has_results()
           ^^^^^^^^^^^^^^^^^^^^^^
  File "C:\Users\melie\AppData\Local\Programs\Python\Python312\Lib\site-packages\django\db\models\sql\compiler.py", line 1542, in has_results
    return bool(self.execute_sql(SINGLE))
                ^^^^^^^^^^^^^^^^^^^^^^^^
  File "C:\Users\melie\AppData\Local\Programs\Python\Python312\Lib\site-packages\django\db\models\sql\compiler.py", line 1574, in execute_sql
    cursor.execute(sql, params)
  File "C:\Users\melie\AppData\Local\Programs\Python\Python312\Lib\site-packages\django\db\backends\utils.py", line 122, in execute
    return super().execute(sql, params)
           ^^^^^^^^^^^^^^^^^^^^^^^^^^^^
  File "C:\Users\melie\AppData\Local\Programs\Python\Python312\Lib\site-packages\django\db\backends\utils.py", line 79, in execute
    return self._execute_with_wrappers(
           ^^^^^^^^^^^^^^^^^^^^^^^^^^^^
  File "C:\Users\melie\AppData\Local\Programs\Python\Python312\Lib\site-packages\django\db\backends\utils.py", line 92, in _execute_with_wrappers
    return executor(sql, params, many, context)
           ^^^^^^^^^^^^^^^^^^^^^^^^^^^^^^^^^^^^
  File "C:\Users\melie\AppData\Local\Programs\Python\Python312\Lib\site-packages\django\db\backends\utils.py", line 100, in _execute
    with self.db.wrap_database_errors:
  File "C:\Users\melie\AppData\Local\Programs\Python\Python312\Lib\site-packages\django\db\utils.py", line 91, in __exit__
    raise dj_exc_value.with_traceback(traceback) from exc_value
  File "C:\Users\melie\AppData\Local\Programs\Python\Python312\Lib\site-packages\django\db\backends\utils.py", line 105, in _execute
    return self.cursor.execute(sql, params)
           ^^^^^^^^^^^^^^^^^^^^^^^^^^^^^^^^
  File "C:\Users\melie\AppData\Local\Programs\Python\Python312\Lib\site-packages\django\db\backends\sqlite3\base.py", line 354, in execute
    return super().execute(query, params)
           ^^^^^^^^^^^^^^^^^^^^^^^^^^^^^^
django.db.utils.OperationalError: no such table: users_customuser
"POST /users/register/ HTTP/1.1" 500 146552
Watching for file changes with StatReloader
Watching for file changes with StatReloader
Internal Server Error: /users/register/
Traceback (most recent call last):
  File "C:\Users\melie\AppData\Local\Programs\Python\Python312\Lib\site-packages\django\db\backends\utils.py", line 105, in _execute
    return self.cursor.execute(sql, params)
           ^^^^^^^^^^^^^^^^^^^^^^^^^^^^^^^^
  File "C:\Users\melie\AppData\Local\Programs\Python\Python312\Lib\site-packages\django\db\backends\sqlite3\base.py", line 354, in execute
    return super().execute(query, params)
           ^^^^^^^^^^^^^^^^^^^^^^^^^^^^^^
sqlite3.OperationalError: no such table: users_customuser

The above exception was the direct cause of the following exception:

Traceback (most recent call last):
  File "C:\Users\melie\AppData\Local\Programs\Python\Python312\Lib\site-packages\django\core\handlers\exception.py", line 55, in inner
    response = get_response(request)
               ^^^^^^^^^^^^^^^^^^^^^
  File "C:\Users\melie\AppData\Local\Programs\Python\Python312\Lib\site-packages\django\core\handlers\base.py", line 197, in _get_response
    response = wrapped_callback(request, *callback_args, **callback_kwargs)
               ^^^^^^^^^^^^^^^^^^^^^^^^^^^^^^^^^^^^^^^^^^^^^^^^^^^^^^^^^^^^
  File "C:\Users\melie\ssa_project\users\views.py", line 85, in register
    if form.is_valid():
       ^^^^^^^^^^^^^^^
  File "C:\Users\melie\AppData\Local\Programs\Python\Python312\Lib\site-packages\django\forms\forms.py", line 197, in is_valid
    return self.is_bound and not self.errors
                                 ^^^^^^^^^^^
  File "C:\Users\melie\AppData\Local\Programs\Python\Python312\Lib\site-packages\django\forms\forms.py", line 192, in errors
    self.full_clean()
  File "C:\Users\melie\AppData\Local\Programs\Python\Python312\Lib\site-packages\django\forms\forms.py", line 325, in full_clean
    self._clean_fields()
  File "C:\Users\melie\AppData\Local\Programs\Python\Python312\Lib\site-packages\django\forms\forms.py", line 335, in _clean_fields
    value = getattr(self, "clean_%s" % name)()
            ^^^^^^^^^^^^^^^^^^^^^^^^^^^^^^^^^^
  File "C:\Users\melie\AppData\Local\Programs\Python\Python312\Lib\site-packages\django\contrib\auth\forms.py", line 268, in clean_username
    and self._meta.model.objects.filter(username__iexact=username).exists()
        ^^^^^^^^^^^^^^^^^^^^^^^^^^^^^^^^^^^^^^^^^^^^^^^^^^^^^^^^^^^^^^^^^^^
  File "C:\Users\melie\AppData\Local\Programs\Python\Python312\Lib\site-packages\django\db\models\query.py", line 1288, in exists
    return self.query.has_results(using=self.db)
           ^^^^^^^^^^^^^^^^^^^^^^^^^^^^^^^^^^^^^
  File "C:\Users\melie\AppData\Local\Programs\Python\Python312\Lib\site-packages\django\db\models\sql\query.py", line 660, in has_results
    return compiler.has_results()
           ^^^^^^^^^^^^^^^^^^^^^^
  File "C:\Users\melie\AppData\Local\Programs\Python\Python312\Lib\site-packages\django\db\models\sql\compiler.py", line 1542, in has_results
    return bool(self.execute_sql(SINGLE))
                ^^^^^^^^^^^^^^^^^^^^^^^^
  File "C:\Users\melie\AppData\Local\Programs\Python\Python312\Lib\site-packages\django\db\models\sql\compiler.py", line 1574, in execute_sql
    cursor.execute(sql, params)
  File "C:\Users\melie\AppData\Local\Programs\Python\Python312\Lib\site-packages\django\db\backends\utils.py", line 122, in execute
    return super().execute(sql, params)
           ^^^^^^^^^^^^^^^^^^^^^^^^^^^^
  File "C:\Users\melie\AppData\Local\Programs\Python\Python312\Lib\site-packages\django\db\backends\utils.py", line 79, in execute
    return self._execute_with_wrappers(
           ^^^^^^^^^^^^^^^^^^^^^^^^^^^^
  File "C:\Users\melie\AppData\Local\Programs\Python\Python312\Lib\site-packages\django\db\backends\utils.py", line 92, in _execute_with_wrappers
    return executor(sql, params, many, context)
           ^^^^^^^^^^^^^^^^^^^^^^^^^^^^^^^^^^^^
  File "C:\Users\melie\AppData\Local\Programs\Python\Python312\Lib\site-packages\django\db\backends\utils.py", line 100, in _execute
    with self.db.wrap_database_errors:
  File "C:\Users\melie\AppData\Local\Programs\Python\Python312\Lib\site-packages\django\db\utils.py", line 91, in __exit__
    raise dj_exc_value.with_traceback(traceback) from exc_value
  File "C:\Users\melie\AppData\Local\Programs\Python\Python312\Lib\site-packages\django\db\backends\utils.py", line 105, in _execute
    return self.cursor.execute(sql, params)
           ^^^^^^^^^^^^^^^^^^^^^^^^^^^^^^^^
  File "C:\Users\melie\AppData\Local\Programs\Python\Python312\Lib\site-packages\django\db\backends\sqlite3\base.py", line 354, in execute
    return super().execute(query, params)
           ^^^^^^^^^^^^^^^^^^^^^^^^^^^^^^
django.db.utils.OperationalError: no such table: users_customuser
"POST /users/register/ HTTP/1.1" 500 146552
Watching for file changes with StatReloader
Internal Server Error: /users/register/
Traceback (most recent call last):
  File "C:\Users\melie\AppData\Local\Programs\Python\Python312\Lib\site-packages\django\core\handlers\exception.py", line 55, in inner
    response = get_response(request)
               ^^^^^^^^^^^^^^^^^^^^^
  File "C:\Users\melie\AppData\Local\Programs\Python\Python312\Lib\site-packages\django\core\handlers\base.py", line 197, in _get_response
    response = wrapped_callback(request, *callback_args, **callback_kwargs)
               ^^^^^^^^^^^^^^^^^^^^^^^^^^^^^^^^^^^^^^^^^^^^^^^^^^^^^^^^^^^^
  File "C:\Users\melie\ssa_project\users\views.py", line 86, in register
    form.save()
  File "C:\Users\melie\ssa_project\users\forms.py", line 34, in save
    profile = user.profile
              ^^^^^^^^^^^^
  File "C:\Users\melie\AppData\Local\Programs\Python\Python312\Lib\site-packages\django\db\models\fields\related_descriptors.py", line 531, in __get__
    raise self.RelatedObjectDoesNotExist(
users.models.CustomUser.profile.RelatedObjectDoesNotExist: CustomUser has no profile.
"POST /users/register/ HTTP/1.1" 500 74394
C:\Users\melie\ssa_project\users\models.py changed, reloading.
Watching for file changes with StatReloader
"POST /users/register/ HTTP/1.1" 200 3054
"GET /static/chipin/styles.css HTTP/1.1" 304 0
"POST /users/register/ HTTP/1.1" 200 3054
Watching for file changes with StatReloader
"POST /users/register/ HTTP/1.1" 302 0
"GET /users/login/ HTTP/1.1" 200 1942
"POST /users/login/ HTTP/1.1" 302 0
"GET /users/login/ HTTP/1.1" 200 1936
"POST /users/login/ HTTP/1.1" 302 0
"GET /users/login/ HTTP/1.1" 200 1936
"GET /users/login/ HTTP/1.1" 200 1787
"POST /users/login/ HTTP/1.1" 200 1919
"POST /users/login/ HTTP/1.1" 200 1919
"GET /users/login/ HTTP/1.1" 200 1787
"POST /users/login/ HTTP/1.1" 302 0
"GET /users/login/ HTTP/1.1" 200 1936
"GET /users/login/ HTTP/1.1" 200 1787
"GET /users/login/ HTTP/1.1" 200 1787
"POST /users/login/ HTTP/1.1" 302 0
"GET /users/ HTTP/1.1" 200 972
"GET /chipin/ HTTP/1.1" 200 981
Watching for file changes with StatReloader
"GET /users/ HTTP/1.1" 302 0
"GET /users/login/?next=/users/ HTTP/1.1" 200 1787
"GET /static/chipin/styles.css HTTP/1.1" 304 0
"POST /users/login/ HTTP/1.1" 302 0
"GET /users/login/ HTTP/1.1" 200 1936
"GET /users/login/ HTTP/1.1" 200 2021
"POST /users/login/ HTTP/1.1" 302 0
"GET /users/ HTTP/1.1" 200 976
"GET /chipin/ HTTP/1.1" 200 986
"GET /chipin/create_group/ HTTP/1.1" 200 1281
Internal Server Error: /chipin/create_group/
Traceback (most recent call last):
  File "C:\Users\melie\AppData\Local\Programs\Python\Python312\Lib\site-packages\django\core\handlers\exception.py", line 55, in inner
    response = get_response(request)
               ^^^^^^^^^^^^^^^^^^^^^
  File "C:\Users\melie\AppData\Local\Programs\Python\Python312\Lib\site-packages\django\core\handlers\base.py", line 197, in _get_response
    response = wrapped_callback(request, *callback_args, **callback_kwargs)
               ^^^^^^^^^^^^^^^^^^^^^^^^^^^^^^^^^^^^^^^^^^^^^^^^^^^^^^^^^^^^
  File "C:\Users\melie\AppData\Local\Programs\Python\Python312\Lib\site-packages\django\contrib\auth\decorators.py", line 60, in _view_wrapper
    return view_func(request, *args, **kwargs)
           ^^^^^^^^^^^^^^^^^^^^^^^^^^^^^^^^^^^
  File "C:\Users\melie\ssa_project\chipin\views.py", line 29, in create_group
    logger.info(
    ^^^^^^
NameError: name 'logger' is not defined
"POST /chipin/create_group/ HTTP/1.1" 500 70118
C:\Users\melie\ssa_project\chipin\views.py changed, reloading.
Watching for file changes with StatReloader
C:\Users\melie\ssa_project\chipin\views.py changed, reloading.
Watching for file changes with StatReloader
C:\Users\melie\ssa_project\chipin\views.py changed, reloading.
Watching for file changes with StatReloader
Internal Server Error: /chipin/create_group/
Traceback (most recent call last):
  File "C:\Users\melie\AppData\Local\Programs\Python\Python312\Lib\site-packages\django\core\handlers\exception.py", line 55, in inner
    response = get_response(request)
               ^^^^^^^^^^^^^^^^^^^^^
  File "C:\Users\melie\AppData\Local\Programs\Python\Python312\Lib\site-packages\django\core\handlers\base.py", line 197, in _get_response
    response = wrapped_callback(request, *callback_args, **callback_kwargs)
               ^^^^^^^^^^^^^^^^^^^^^^^^^^^^^^^^^^^^^^^^^^^^^^^^^^^^^^^^^^^^
  File "C:\Users\melie\AppData\Local\Programs\Python\Python312\Lib\site-packages\django\contrib\auth\decorators.py", line 60, in _view_wrapper
    return view_func(request, *args, **kwargs)
           ^^^^^^^^^^^^^^^^^^^^^^^^^^^^^^^^^^^
  File "C:\Users\melie\ssa_project\chipin\views.py", line 38, in create_group
    return redirect("group_detail", group_id=group.id)
           ^^^^^^^^^^^^^^^^^^^^^^^^^^^^^^^^^^^^^^^^^^^
  File "C:\Users\melie\AppData\Local\Programs\Python\Python312\Lib\site-packages\django\shortcuts.py", line 49, in redirect
    return redirect_class(resolve_url(to, *args, **kwargs))
                          ^^^^^^^^^^^^^^^^^^^^^^^^^^^^^^^^
  File "C:\Users\melie\AppData\Local\Programs\Python\Python312\Lib\site-packages\django\shortcuts.py", line 180, in resolve_url
    return reverse(to, args=args, kwargs=kwargs)
           ^^^^^^^^^^^^^^^^^^^^^^^^^^^^^^^^^^^^^
  File "C:\Users\melie\AppData\Local\Programs\Python\Python312\Lib\site-packages\django\urls\base.py", line 88, in reverse
    return resolver._reverse_with_prefix(view, prefix, *args, **kwargs)
           ^^^^^^^^^^^^^^^^^^^^^^^^^^^^^^^^^^^^^^^^^^^^^^^^^^^^^^^^^^^^
  File "C:\Users\melie\AppData\Local\Programs\Python\Python312\Lib\site-packages\django\urls\resolvers.py", line 831, in _reverse_with_prefix
    raise NoReverseMatch(msg)
django.urls.exceptions.NoReverseMatch: Reverse for 'group_detail' not found. 'group_detail' is not a valid view function or pattern name.
"POST /chipin/create_group/ HTTP/1.1" 500 89432
"GET /chipin/create_group/ HTTP/1.1" 200 1431
Internal Server Error: /chipin/create_group/
Traceback (most recent call last):
  File "C:\Users\melie\AppData\Local\Programs\Python\Python312\Lib\site-packages\django\core\handlers\exception.py", line 55, in inner
    response = get_response(request)
               ^^^^^^^^^^^^^^^^^^^^^
  File "C:\Users\melie\AppData\Local\Programs\Python\Python312\Lib\site-packages\django\core\handlers\base.py", line 197, in _get_response
    response = wrapped_callback(request, *callback_args, **callback_kwargs)
               ^^^^^^^^^^^^^^^^^^^^^^^^^^^^^^^^^^^^^^^^^^^^^^^^^^^^^^^^^^^^
  File "C:\Users\melie\AppData\Local\Programs\Python\Python312\Lib\site-packages\django\contrib\auth\decorators.py", line 60, in _view_wrapper
    return view_func(request, *args, **kwargs)
           ^^^^^^^^^^^^^^^^^^^^^^^^^^^^^^^^^^^
  File "C:\Users\melie\ssa_project\chipin\views.py", line 38, in create_group
    return redirect("group_detail", group_id=group.id)
           ^^^^^^^^^^^^^^^^^^^^^^^^^^^^^^^^^^^^^^^^^^^
  File "C:\Users\melie\AppData\Local\Programs\Python\Python312\Lib\site-packages\django\shortcuts.py", line 49, in redirect
    return redirect_class(resolve_url(to, *args, **kwargs))
                          ^^^^^^^^^^^^^^^^^^^^^^^^^^^^^^^^
  File "C:\Users\melie\AppData\Local\Programs\Python\Python312\Lib\site-packages\django\shortcuts.py", line 180, in resolve_url
    return reverse(to, args=args, kwargs=kwargs)
           ^^^^^^^^^^^^^^^^^^^^^^^^^^^^^^^^^^^^^
  File "C:\Users\melie\AppData\Local\Programs\Python\Python312\Lib\site-packages\django\urls\base.py", line 88, in reverse
    return resolver._reverse_with_prefix(view, prefix, *args, **kwargs)
           ^^^^^^^^^^^^^^^^^^^^^^^^^^^^^^^^^^^^^^^^^^^^^^^^^^^^^^^^^^^^
  File "C:\Users\melie\AppData\Local\Programs\Python\Python312\Lib\site-packages\django\urls\resolvers.py", line 831, in _reverse_with_prefix
    raise NoReverseMatch(msg)
django.urls.exceptions.NoReverseMatch: Reverse for 'group_detail' not found. 'group_detail' is not a valid view function or pattern name.
"POST /chipin/create_group/ HTTP/1.1" 500 89432
C:\Users\melie\ssa_project\chipin\urls.py changed, reloading.
Watching for file changes with StatReloader
Internal Server Error: /chipin/create_group/
Traceback (most recent call last):
  File "C:\Users\melie\AppData\Local\Programs\Python\Python312\Lib\site-packages\django\core\handlers\exception.py", line 55, in inner
    response = get_response(request)
               ^^^^^^^^^^^^^^^^^^^^^
  File "C:\Users\melie\AppData\Local\Programs\Python\Python312\Lib\site-packages\django\core\handlers\base.py", line 197, in _get_response
    response = wrapped_callback(request, *callback_args, **callback_kwargs)
               ^^^^^^^^^^^^^^^^^^^^^^^^^^^^^^^^^^^^^^^^^^^^^^^^^^^^^^^^^^^^
  File "C:\Users\melie\AppData\Local\Programs\Python\Python312\Lib\site-packages\django\contrib\auth\decorators.py", line 60, in _view_wrapper
    return view_func(request, *args, **kwargs)
           ^^^^^^^^^^^^^^^^^^^^^^^^^^^^^^^^^^^
  File "C:\Users\melie\ssa_project\chipin\views.py", line 38, in create_group
    return redirect("group_detail", group_id=group.id)
           ^^^^^^^^^^^^^^^^^^^^^^^^^^^^^^^^^^^^^^^^^^^
  File "C:\Users\melie\AppData\Local\Programs\Python\Python312\Lib\site-packages\django\shortcuts.py", line 49, in redirect
    return redirect_class(resolve_url(to, *args, **kwargs))
                          ^^^^^^^^^^^^^^^^^^^^^^^^^^^^^^^^
  File "C:\Users\melie\AppData\Local\Programs\Python\Python312\Lib\site-packages\django\shortcuts.py", line 180, in resolve_url
    return reverse(to, args=args, kwargs=kwargs)
           ^^^^^^^^^^^^^^^^^^^^^^^^^^^^^^^^^^^^^
  File "C:\Users\melie\AppData\Local\Programs\Python\Python312\Lib\site-packages\django\urls\base.py", line 88, in reverse
    return resolver._reverse_with_prefix(view, prefix, *args, **kwargs)
           ^^^^^^^^^^^^^^^^^^^^^^^^^^^^^^^^^^^^^^^^^^^^^^^^^^^^^^^^^^^^
  File "C:\Users\melie\AppData\Local\Programs\Python\Python312\Lib\site-packages\django\urls\resolvers.py", line 831, in _reverse_with_prefix
    raise NoReverseMatch(msg)
django.urls.exceptions.NoReverseMatch: Reverse for 'group_detail' not found. 'group_detail' is not a valid view function or pattern name.
"POST /chipin/create_group/ HTTP/1.1" 500 89702
Internal Server Error: /chipin/create_group/
Traceback (most recent call last):
  File "C:\Users\melie\AppData\Local\Programs\Python\Python312\Lib\site-packages\django\core\handlers\exception.py", line 55, in inner
    response = get_response(request)
               ^^^^^^^^^^^^^^^^^^^^^
  File "C:\Users\melie\AppData\Local\Programs\Python\Python312\Lib\site-packages\django\core\handlers\base.py", line 197, in _get_response
    response = wrapped_callback(request, *callback_args, **callback_kwargs)
               ^^^^^^^^^^^^^^^^^^^^^^^^^^^^^^^^^^^^^^^^^^^^^^^^^^^^^^^^^^^^
  File "C:\Users\melie\AppData\Local\Programs\Python\Python312\Lib\site-packages\django\contrib\auth\decorators.py", line 60, in _view_wrapper
    return view_func(request, *args, **kwargs)
           ^^^^^^^^^^^^^^^^^^^^^^^^^^^^^^^^^^^
  File "C:\Users\melie\ssa_project\chipin\views.py", line 38, in create_group
    return redirect("group_detail", group_id=group.id)
           ^^^^^^^^^^^^^^^^^^^^^^^^^^^^^^^^^^^^^^^^^^^
  File "C:\Users\melie\AppData\Local\Programs\Python\Python312\Lib\site-packages\django\shortcuts.py", line 49, in redirect
    return redirect_class(resolve_url(to, *args, **kwargs))
                          ^^^^^^^^^^^^^^^^^^^^^^^^^^^^^^^^
  File "C:\Users\melie\AppData\Local\Programs\Python\Python312\Lib\site-packages\django\shortcuts.py", line 180, in resolve_url
    return reverse(to, args=args, kwargs=kwargs)
           ^^^^^^^^^^^^^^^^^^^^^^^^^^^^^^^^^^^^^
  File "C:\Users\melie\AppData\Local\Programs\Python\Python312\Lib\site-packages\django\urls\base.py", line 88, in reverse
    return resolver._reverse_with_prefix(view, prefix, *args, **kwargs)
           ^^^^^^^^^^^^^^^^^^^^^^^^^^^^^^^^^^^^^^^^^^^^^^^^^^^^^^^^^^^^
  File "C:\Users\melie\AppData\Local\Programs\Python\Python312\Lib\site-packages\django\urls\resolvers.py", line 831, in _reverse_with_prefix
    raise NoReverseMatch(msg)
django.urls.exceptions.NoReverseMatch: Reverse for 'group_detail' not found. 'group_detail' is not a valid view function or pattern name.
"POST /chipin/create_group/ HTTP/1.1" 500 89716
C:\Users\melie\ssa_project\chipin\views.py changed, reloading.
Watching for file changes with StatReloader
"POST /chipin/create_group/ HTTP/1.1" 302 0
"GET /chipin/group/6/ HTTP/1.1" 200 1440
"GET /chipin/group/6/invite/ HTTP/1.1" 200 1289
Watching for file changes with StatReloader
"GET /chipin/create_group/ HTTP/1.1" 200 1281
"POST /users/logout/ HTTP/1.1" 302 0
"GET /users/login/ HTTP/1.1" 200 1916
"POST /users/login/ HTTP/1.1" 302 0
"GET /users/ HTTP/1.1" 200 976
"GET /chipin/ HTTP/1.1" 200 2231
"GET /chipin/group/1/delete/ HTTP/1.1" 302 0
"GET /chipin/ HTTP/1.1" 200 2160
"GET /chipin/group/2/delete/ HTTP/1.1" 302 0
"GET /chipin/ HTTP/1.1" 200 1943
"GET /chipin/group/3/delete/ HTTP/1.1" 302 0
"GET /chipin/ HTTP/1.1" 200 1726
"GET /chipin/group/4/delete/ HTTP/1.1" 302 0
"GET /chipin/ HTTP/1.1" 200 1509
"GET /chipin/group/5/delete/ HTTP/1.1" 302 0
"GET /chipin/ HTTP/1.1" 200 1292
"GET /chipin/group/6/ HTTP/1.1" 200 1014
"GET /chipin/group/6/invite/ HTTP/1.1" 200 1469
"POST /users/logout/ HTTP/1.1" 302 0
"GET /users/login/ HTTP/1.1" 200 1916
"POST /users/login/ HTTP/1.1" 302 0
"GET /users/ HTTP/1.1" 200 959
"GET /chipin/ HTTP/1.1" 200 977
"GET /chipin/create_group/ HTTP/1.1" 200 1272
"POST /chipin/create_group/ HTTP/1.1" 302 0
"GET /chipin/group/7/ HTTP/1.1" 200 1149
"GET /chipin/group/7/invite/ HTTP/1.1" 200 1477
"POST /chipin/group/7/invite/ HTTP/1.1" 302 0
"GET /chipin/group/7/ HTTP/1.1" 200 1129
"POST /users/logout/ HTTP/1.1" 302 0
"GET /users/login/ HTTP/1.1" 200 1916
"POST /users/login/ HTTP/1.1" 302 0
"GET /users/ HTTP/1.1" 200 976
"GET /chipin/ HTTP/1.1" 200 1459
Internal Server Error: /chipin/accept-invite/7/
Traceback (most recent call last):
  File "C:\Users\melie\AppData\Local\Programs\Python\Python312\Lib\site-packages\django\db\backends\utils.py", line 105, in _execute
    return self.cursor.execute(sql, params)
           ^^^^^^^^^^^^^^^^^^^^^^^^^^^^^^^^
  File "C:\Users\melie\AppData\Local\Programs\Python\Python312\Lib\site-packages\django\db\backends\sqlite3\base.py", line 354, in execute
    return super().execute(query, params)
           ^^^^^^^^^^^^^^^^^^^^^^^^^^^^^^
sqlite3.OperationalError: no such table: auth_user

The above exception was the direct cause of the following exception:

Traceback (most recent call last):
  File "C:\Users\melie\AppData\Local\Programs\Python\Python312\Lib\site-packages\django\core\handlers\exception.py", line 55, in inner
    response = get_response(request)
               ^^^^^^^^^^^^^^^^^^^^^
  File "C:\Users\melie\AppData\Local\Programs\Python\Python312\Lib\site-packages\django\core\handlers\base.py", line 197, in _get_response
    response = wrapped_callback(request, *callback_args, **callback_kwargs)
               ^^^^^^^^^^^^^^^^^^^^^^^^^^^^^^^^^^^^^^^^^^^^^^^^^^^^^^^^^^^^
  File "C:\Users\melie\AppData\Local\Programs\Python\Python312\Lib\site-packages\django\contrib\auth\decorators.py", line 60, in _view_wrapper
    return view_func(request, *args, **kwargs)
           ^^^^^^^^^^^^^^^^^^^^^^^^^^^^^^^^^^^
  File "C:\Users\melie\ssa_project\chipin\views.py", line 92, in accept_invite
    invited_user = get_object_or_404(User, id=user_id)
                   ^^^^^^^^^^^^^^^^^^^^^^^^^^^^^^^^^^^
  File "C:\Users\melie\AppData\Local\Programs\Python\Python312\Lib\site-packages\django\shortcuts.py", line 86, in get_object_or_404
    return queryset.get(*args, **kwargs)
           ^^^^^^^^^^^^^^^^^^^^^^^^^^^^^
  File "C:\Users\melie\AppData\Local\Programs\Python\Python312\Lib\site-packages\django\db\models\query.py", line 645, in get
    num = len(clone)
          ^^^^^^^^^^
  File "C:\Users\melie\AppData\Local\Programs\Python\Python312\Lib\site-packages\django\db\models\query.py", line 382, in __len__
    self._fetch_all()
  File "C:\Users\melie\AppData\Local\Programs\Python\Python312\Lib\site-packages\django\db\models\query.py", line 1928, in _fetch_all
    self._result_cache = list(self._iterable_class(self))
                         ^^^^^^^^^^^^^^^^^^^^^^^^^^^^^^^^
  File "C:\Users\melie\AppData\Local\Programs\Python\Python312\Lib\site-packages\django\db\models\query.py", line 91, in __iter__
    results = compiler.execute_sql(
              ^^^^^^^^^^^^^^^^^^^^^
  File "C:\Users\melie\AppData\Local\Programs\Python\Python312\Lib\site-packages\django\db\models\sql\compiler.py", line 1574, in execute_sql
    cursor.execute(sql, params)
  File "C:\Users\melie\AppData\Local\Programs\Python\Python312\Lib\site-packages\django\db\backends\utils.py", line 122, in execute
    return super().execute(sql, params)
           ^^^^^^^^^^^^^^^^^^^^^^^^^^^^
  File "C:\Users\melie\AppData\Local\Programs\Python\Python312\Lib\site-packages\django\db\backends\utils.py", line 79, in execute
    return self._execute_with_wrappers(
           ^^^^^^^^^^^^^^^^^^^^^^^^^^^^
  File "C:\Users\melie\AppData\Local\Programs\Python\Python312\Lib\site-packages\django\db\backends\utils.py", line 92, in _execute_with_wrappers
    return executor(sql, params, many, context)
           ^^^^^^^^^^^^^^^^^^^^^^^^^^^^^^^^^^^^
  File "C:\Users\melie\AppData\Local\Programs\Python\Python312\Lib\site-packages\django\db\backends\utils.py", line 100, in _execute
    with self.db.wrap_database_errors:
  File "C:\Users\melie\AppData\Local\Programs\Python\Python312\Lib\site-packages\django\db\utils.py", line 91, in __exit__
    raise dj_exc_value.with_traceback(traceback) from exc_value
  File "C:\Users\melie\AppData\Local\Programs\Python\Python312\Lib\site-packages\django\db\backends\utils.py", line 105, in _execute
    return self.cursor.execute(sql, params)
           ^^^^^^^^^^^^^^^^^^^^^^^^^^^^^^^^
  File "C:\Users\melie\AppData\Local\Programs\Python\Python312\Lib\site-packages\django\db\backends\sqlite3\base.py", line 354, in execute
    return super().execute(query, params)
           ^^^^^^^^^^^^^^^^^^^^^^^^^^^^^^
django.db.utils.OperationalError: no such table: auth_user
"GET /chipin/accept-invite/7/?user_id=1 HTTP/1.1" 500 143726
Internal Server Error: /chipin/accept-invite/7/
Traceback (most recent call last):
  File "C:\Users\melie\AppData\Local\Programs\Python\Python312\Lib\site-packages\django\db\backends\utils.py", line 105, in _execute
    return self.cursor.execute(sql, params)
           ^^^^^^^^^^^^^^^^^^^^^^^^^^^^^^^^
  File "C:\Users\melie\AppData\Local\Programs\Python\Python312\Lib\site-packages\django\db\backends\sqlite3\base.py", line 354, in execute
    return super().execute(query, params)
           ^^^^^^^^^^^^^^^^^^^^^^^^^^^^^^
sqlite3.OperationalError: no such table: auth_user

The above exception was the direct cause of the following exception:

Traceback (most recent call last):
  File "C:\Users\melie\AppData\Local\Programs\Python\Python312\Lib\site-packages\django\core\handlers\exception.py", line 55, in inner
    response = get_response(request)
               ^^^^^^^^^^^^^^^^^^^^^
  File "C:\Users\melie\AppData\Local\Programs\Python\Python312\Lib\site-packages\django\core\handlers\base.py", line 197, in _get_response
    response = wrapped_callback(request, *callback_args, **callback_kwargs)
               ^^^^^^^^^^^^^^^^^^^^^^^^^^^^^^^^^^^^^^^^^^^^^^^^^^^^^^^^^^^^
  File "C:\Users\melie\AppData\Local\Programs\Python\Python312\Lib\site-packages\django\contrib\auth\decorators.py", line 60, in _view_wrapper
    return view_func(request, *args, **kwargs)
           ^^^^^^^^^^^^^^^^^^^^^^^^^^^^^^^^^^^
  File "C:\Users\melie\ssa_project\chipin\views.py", line 92, in accept_invite
    invited_user = get_object_or_404(CustomUser, id=user_id)
                   ^^^^^^^^^^^^^^^^^^^^^^^^^^^^^^^^^^^
  File "C:\Users\melie\AppData\Local\Programs\Python\Python312\Lib\site-packages\django\shortcuts.py", line 86, in get_object_or_404
    return queryset.get(*args, **kwargs)
           ^^^^^^^^^^^^^^^^^^^^^^^^^^^^^
  File "C:\Users\melie\AppData\Local\Programs\Python\Python312\Lib\site-packages\django\db\models\query.py", line 645, in get
    num = len(clone)
          ^^^^^^^^^^
  File "C:\Users\melie\AppData\Local\Programs\Python\Python312\Lib\site-packages\django\db\models\query.py", line 382, in __len__
    self._fetch_all()
  File "C:\Users\melie\AppData\Local\Programs\Python\Python312\Lib\site-packages\django\db\models\query.py", line 1928, in _fetch_all
    self._result_cache = list(self._iterable_class(self))
                         ^^^^^^^^^^^^^^^^^^^^^^^^^^^^^^^^
  File "C:\Users\melie\AppData\Local\Programs\Python\Python312\Lib\site-packages\django\db\models\query.py", line 91, in __iter__
    results = compiler.execute_sql(
              ^^^^^^^^^^^^^^^^^^^^^
  File "C:\Users\melie\AppData\Local\Programs\Python\Python312\Lib\site-packages\django\db\models\sql\compiler.py", line 1574, in execute_sql
    cursor.execute(sql, params)
  File "C:\Users\melie\AppData\Local\Programs\Python\Python312\Lib\site-packages\django\db\backends\utils.py", line 122, in execute
    return super().execute(sql, params)
           ^^^^^^^^^^^^^^^^^^^^^^^^^^^^
  File "C:\Users\melie\AppData\Local\Programs\Python\Python312\Lib\site-packages\django\db\backends\utils.py", line 79, in execute
    return self._execute_with_wrappers(
           ^^^^^^^^^^^^^^^^^^^^^^^^^^^^
  File "C:\Users\melie\AppData\Local\Programs\Python\Python312\Lib\site-packages\django\db\backends\utils.py", line 92, in _execute_with_wrappers
    return executor(sql, params, many, context)
           ^^^^^^^^^^^^^^^^^^^^^^^^^^^^^^^^^^^^
  File "C:\Users\melie\AppData\Local\Programs\Python\Python312\Lib\site-packages\django\db\backends\utils.py", line 100, in _execute
    with self.db.wrap_database_errors:
  File "C:\Users\melie\AppData\Local\Programs\Python\Python312\Lib\site-packages\django\db\utils.py", line 91, in __exit__
    raise dj_exc_value.with_traceback(traceback) from exc_value
  File "C:\Users\melie\AppData\Local\Programs\Python\Python312\Lib\site-packages\django\db\backends\utils.py", line 105, in _execute
    return self.cursor.execute(sql, params)
           ^^^^^^^^^^^^^^^^^^^^^^^^^^^^^^^^
  File "C:\Users\melie\AppData\Local\Programs\Python\Python312\Lib\site-packages\django\db\backends\sqlite3\base.py", line 354, in execute
    return super().execute(query, params)
           ^^^^^^^^^^^^^^^^^^^^^^^^^^^^^^
django.db.utils.OperationalError: no such table: auth_user
"GET /chipin/accept-invite/7/?user_id=1 HTTP/1.1" 500 143875
C:\Users\melie\ssa_project\chipin\views.py changed, reloading.
Watching for file changes with StatReloader
"GET /chipin/accept-invite/7/?user_id=1 HTTP/1.1" 302 0
"GET /chipin/group/7/ HTTP/1.1" 200 1211
"POST /users/logout/ HTTP/1.1" 302 0
"GET /users/login/ HTTP/1.1" 200 1916
"POST /users/login/ HTTP/1.1" 302 0
"GET /users/ HTTP/1.1" 200 959
"GET /chipin/ HTTP/1.1" 200 1141
"GET /chipin/group/7/delete/ HTTP/1.1" 302 0
"GET /chipin/ HTTP/1.1" 200 1127
"GET /chipin/create_group/ HTTP/1.1" 200 1272
"POST /chipin/create_group/ HTTP/1.1" 302 0
"GET /chipin/group/8/ HTTP/1.1" 200 1131
"GET /chipin/group/8/invite/ HTTP/1.1" 200 1465
"GET /chipin/group/8/invite/ HTTP/1.1" 200 1342
"POST /chipin/group/8/invite/ HTTP/1.1" 302 0
"GET /chipin/group/8/ HTTP/1.1" 200 1117
"POST /users/logout/ HTTP/1.1" 302 0
"GET /users/login/ HTTP/1.1" 200 1916
"POST /users/login/ HTTP/1.1" 302 0
"GET /users/ HTTP/1.1" 200 976
"GET /chipin/ HTTP/1.1" 200 1453
"GET /chipin/accept-invite/8/?user_id=1 HTTP/1.1" 302 0
"GET /chipin/group/8/ HTTP/1.1" 200 1193
"GET /chipin/group/8/invite/ HTTP/1.1" 200 1285
"POST /users/logout/ HTTP/1.1" 302 0
"GET /users/login/ HTTP/1.1" 200 1916
Watching for file changes with StatReloader
"GET /users/ HTTP/1.1" 302 0
"GET /users/login/?next=/users/ HTTP/1.1" 200 1787
"GET /static/chipin/styles.css HTTP/1.1" 304 0
Watching for file changes with StatReloader
"GET /users/ HTTP/1.1" 302 0
"GET /users/login/?next=/users/ HTTP/1.1" 200 1787
"POST /users/login/ HTTP/1.1" 302 0
"GET /users/ HTTP/1.1" 200 976
"GET /chipin/ HTTP/1.1" 200 1840
"GET /chipin/group/6/delete/ HTTP/1.1" 302 0
"GET /chipin/ HTTP/1.1" 200 1741
"GET /chipin/create_group/ HTTP/1.1" 200 1281
"POST /chipin/create_group/ HTTP/1.1" 302 0
"GET /chipin/group/9/ HTTP/1.1" 200 1473
"GET /chipin/group/9/invite/ HTTP/1.1" 200 1344
"POST /chipin/group/9/invite/ HTTP/1.1" 302 0
"GET /chipin/group/9/ HTTP/1.1" 200 1449
"POST /users/logout/ HTTP/1.1" 302 0
"GET /users/login/ HTTP/1.1" 200 1916
"POST /users/login/ HTTP/1.1" 302 0
"GET /users/ HTTP/1.1" 200 959
"GET /chipin/ HTTP/1.1" 200 1889
"GET /chipin/group/9/accept/?user_id=2 HTTP/1.1" 302 0
"GET /chipin/group/9/ HTTP/1.1" 200 1435
"GET /admin HTTP/1.1" 301 0
"GET /admin/ HTTP/1.1" 200 6721
"GET /static/admin/css/base.css HTTP/1.1" 200 22092
"GET /static/admin/css/dark_mode.css HTTP/1.1" 200 2804
"GET /static/admin/css/nav_sidebar.css HTTP/1.1" 200 2810
"GET /static/admin/css/dashboard.css HTTP/1.1" 200 441
"GET /static/admin/css/responsive.css HTTP/1.1" 200 17972
"GET /static/admin/js/theme.js HTTP/1.1" 200 1653
"GET /static/admin/js/nav_sidebar.js HTTP/1.1" 200 3063
"GET /static/admin/img/icon-addlink.svg HTTP/1.1" 200 331
"GET /static/admin/img/icon-changelink.svg HTTP/1.1" 200 380
"GET /admin/users/customuser/ HTTP/1.1" 200 12425
"GET /static/admin/js/jquery.init.js HTTP/1.1" 200 347
"GET /static/admin/css/changelists.css HTTP/1.1" 200 6878
"GET /static/admin/js/admin/RelatedObjectLookups.js HTTP/1.1" 200 9097
"GET /static/admin/js/core.js HTTP/1.1" 200 6208
"GET /static/admin/js/actions.js HTTP/1.1" 200 8076
"GET /static/admin/js/urlify.js HTTP/1.1" 200 7887
"GET /admin/jsi18n/ HTTP/1.1" 200 3342
"GET /static/admin/js/prepopulate.js HTTP/1.1" 200 1531
"GET /static/admin/js/vendor/jquery/jquery.js HTTP/1.1" 200 285314
"GET /static/admin/img/search.svg HTTP/1.1" 200 458
"GET /static/admin/img/icon-yes.svg HTTP/1.1" 200 436
"GET /static/admin/js/vendor/xregexp/xregexp.js HTTP/1.1" 200 325171
"GET /static/admin/img/icon-no.svg HTTP/1.1" 200 560
"GET /static/admin/js/filters.js HTTP/1.1" 200 978
"GET /static/admin/img/tooltag-add.svg HTTP/1.1" 200 331
"GET /static/admin/img/icon-viewlink.svg HTTP/1.1" 200 581
"GET /static/admin/img/sorting-icons.svg HTTP/1.1" 200 1097
"GET /admin/users/customuser/2/change/ HTTP/1.1" 200 22780
"GET /static/admin/css/forms.css HTTP/1.1" 200 8794
"GET /admin/jsi18n/ HTTP/1.1" 200 3342
"GET /static/admin/js/calendar.js HTTP/1.1" 200 9141
"GET /static/admin/js/SelectFilter2.js HTTP/1.1" 200 15502
"GET /static/admin/js/SelectBox.js HTTP/1.1" 200 4530
"GET /static/admin/js/admin/DateTimeShortcuts.js HTTP/1.1" 200 19319
"GET /static/admin/js/prepopulate_init.js HTTP/1.1" 200 586
"GET /static/admin/css/widgets.css HTTP/1.1" 200 11564
"GET /static/admin/js/change_form.js HTTP/1.1" 200 606
"GET /static/admin/img/icon-unknown.svg HTTP/1.1" 200 655
"GET /static/admin/img/selector-icons.svg HTTP/1.1" 200 3291
"GET /static/admin/img/icon-clock.svg HTTP/1.1" 200 677
"GET /static/admin/img/icon-unknown-alt.svg HTTP/1.1" 200 655
"GET /static/admin/img/icon-calendar.svg HTTP/1.1" 200 1086
"GET /admin/auth/group/ HTTP/1.1" 200 8170
"GET /admin/jsi18n/ HTTP/1.1" 200 3342
"GET /users/ HTTP/1.1" 200 959
"GET /chipin/ HTTP/1.1" 200 1830
"GET /chipin/create_group/ HTTP/1.1" 200 1272
"POST /chipin/create_group/ HTTP/1.1" 302 0
"GET /chipin/group/10/ HTTP/1.1" 200 1453
"GET /chipin/group/10/invite/ HTTP/1.1" 200 1348
"POST /chipin/group/10/invite/ HTTP/1.1" 302 0
"GET /chipin/group/10/ HTTP/1.1" 200 1436
"GET /chipin/group/10/invite/ HTTP/1.1" 200 1348
"POST /chipin/group/10/invite/ HTTP/1.1" 302 0
"GET /chipin/group/10/ HTTP/1.1" 200 1439
"POST /users/logout/ HTTP/1.1" 302 0
"GET /users/login/ HTTP/1.1" 200 1916
"POST /users/login/ HTTP/1.1" 302 0
"GET /users/ HTTP/1.1" 200 976
"GET /chipin/ HTTP/1.1" 200 2136
"GET /chipin/group/10/accept/?user_id=1 HTTP/1.1" 302 0
"GET /chipin/group/10/ HTTP/1.1" 200 1450
"POST /users/logout/ HTTP/1.1" 302 0
"GET /users/login/ HTTP/1.1" 200 1916
"POST /users/login/ HTTP/1.1" 302 0
"GET /users/ HTTP/1.1" 200 959
"GET /chipin/ HTTP/1.1" 200 2078
"GET /chipin/group/10/delete/ HTTP/1.1" 302 0
"GET /chipin/ HTTP/1.1" 200 1977
"GET /chipin/group/9/leave/ HTTP/1.1" 302 0
"GET /chipin/ HTTP/1.1" 200 1796
"GET /chipin/group/8/delete/ HTTP/1.1" 302 0
"GET /chipin/ HTTP/1.1" 200 1628
"GET /chipin/group/9/ HTTP/1.1" 200 1267
"GET /chipin/group/9/request-to-join/ HTTP/1.1" 302 0
"GET /chipin/group/9/ HTTP/1.1" 200 1422
"POST /users/logout/ HTTP/1.1" 302 0
"GET /users/login/ HTTP/1.1" 200 1916
"POST /users/login/ HTTP/1.1" 302 0
"GET /users/ HTTP/1.1" 200 976
"GET /chipin/ HTTP/1.1" 200 1599
"GET /chipin/group/9/ HTTP/1.1" 200 1569
"GET /chipin/group/9/request/1/vote/approve/ HTTP/1.1" 302 0
"GET /chipin/group/9/ HTTP/1.1" 200 1638
"POST /users/logout/ HTTP/1.1" 302 0
"GET /users/login/ HTTP/1.1" 200 1916
"GET /users/login/ HTTP/1.1" 200 1787
"POST /users/login/ HTTP/1.1" 302 0
"GET /users/ HTTP/1.1" 200 959
"GET /chipin/ HTTP/1.1" 200 1785
"GET /admin/ HTTP/1.1" 200 6721
"GET /admin/users/profile/ HTTP/1.1" 200 11032
"GET /admin/jsi18n/ HTTP/1.1" 200 3342
"GET /admin/users/profile/1/change/ HTTP/1.1" 200 11869
"GET /admin/jsi18n/ HTTP/1.1" 200 3342
"GET /admin/users/profile/ HTTP/1.1" 200 11032
"GET /admin/jsi18n/ HTTP/1.1" 200 3342
"GET /admin/users/profile/?q= HTTP/1.1" 200 11164
"GET /admin/jsi18n/ HTTP/1.1" 200 3342
"GET /admin/users/profile/?q= HTTP/1.1" 200 11164
"GET /admin/jsi18n/ HTTP/1.1" 200 3342
"GET /admin/users/profile/add/?_changelist_filters=q%3D HTTP/1.1" 200 11654
"GET /admin/jsi18n/ HTTP/1.1" 200 3342
"POST /admin/users/profile/add/?_changelist_filters=q%3D HTTP/1.1" 200 11884
"GET /admin/jsi18n/ HTTP/1.1" 200 3342
"GET /admin/users/customuser/add/?_to_field=id&_popup=1 HTTP/1.1" 200 8158
"GET /admin/jsi18n/ HTTP/1.1" 200 3342
"GET /static/admin/css/unusable_password_field.css HTTP/1.1" 200 663
"GET /static/admin/js/unusable_password_field.js HTTP/1.1" 200 1480
"POST /admin/users/profile/add/?_changelist_filters=q%3D HTTP/1.1" 200 11869
"GET /admin/jsi18n/ HTTP/1.1" 200 3342
"POST /admin/users/profile/add/?_changelist_filters=q%3D HTTP/1.1" 200 11869
"GET /admin/jsi18n/ HTTP/1.1" 200 3342
"GET /admin/users/customuser/2/change/?_to_field=id&_popup=1 HTTP/1.1" 200 18317
"GET /admin/jsi18n/ HTTP/1.1" 200 3342
"POST /admin/users/customuser/2/change/?_to_field=id&_popup=1 HTTP/1.1" 200 18512
"GET /admin/jsi18n/ HTTP/1.1" 200 3342
"POST /admin/users/customuser/2/change/?_to_field=id&_popup=1 HTTP/1.1" 200 398
"GET /static/admin/js/popup_response.js HTTP/1.1" 200 532
"GET /admin/users/profile/ HTTP/1.1" 200 11027
"GET /admin/jsi18n/ HTTP/1.1" 200 3342
"POST /admin/users/profile/ HTTP/1.1" 200 7891
"GET /static/admin/js/cancel.js HTTP/1.1" 200 884
"GET /admin/users/profile/2/change/ HTTP/1.1" 200 11832
"GET /admin/jsi18n/ HTTP/1.1" 200 3342
"POST /admin/users/profile/2/change/ HTTP/1.1" 302 0
"GET /admin/users/profile/ HTTP/1.1" 200 11252
"GET /admin/jsi18n/ HTTP/1.1" 200 3342
"GET /admin/users/profile/1/change/ HTTP/1.1" 200 11864
"GET /admin/jsi18n/ HTTP/1.1" 200 3342
"GET /admin/users/customuser/ HTTP/1.1" 200 12427
"GET /admin/jsi18n/ HTTP/1.1" 200 3342
"GET /admin/users/customuser/2/change/ HTTP/1.1" 200 22802
"GET /admin/jsi18n/ HTTP/1.1" 200 3342
Watching for file changes with StatReloader
"GET /admin/users/profile/ HTTP/1.1" 200 11046
"GET /admin/jsi18n/ HTTP/1.1" 200 3342
"GET /admin/ HTTP/1.1" 200 7448
"GET /admin/users/profile/2/change/ HTTP/1.1" 200 11869
"GET /admin/jsi18n/ HTTP/1.1" 200 3342
"GET /admin/users/customuser/2/change/?_to_field=id HTTP/1.1" 200 22851
"GET /admin/jsi18n/ HTTP/1.1" 200 3342
"POST /admin/users/customuser/2/change/?_to_field=id HTTP/1.1" 200 23019
"GET /admin/jsi18n/ HTTP/1.1" 200 3342
"GET /admin/ HTTP/1.1" 200 7448
"GET /admin/ HTTP/1.1" 200 7448
"GET /admin/ HTTP/1.1" 200 7448
Not Found: /user/
"GET /user/ HTTP/1.1" 404 2494
"GET /users/ HTTP/1.1" 200 971
"POST /users/logout/ HTTP/1.1" 302 0
"GET /users/login/ HTTP/1.1" 200 1916
"GET /users/register/ HTTP/1.1" 200 2762
"POST /users/register/ HTTP/1.1" 302 0
"GET /users/login/ HTTP/1.1" 200 1942
- Broken pipe from ('127.0.0.1', 55736)
- Broken pipe from ('127.0.0.1', 63520)
- Broken pipe from ('127.0.0.1', 63523)
- Broken pipe from ('127.0.0.1', 63525)
- Broken pipe from ('127.0.0.1', 63530)
- Broken pipe from ('127.0.0.1', 63533)
"POST /users/login/ HTTP/1.1" 302 0
"GET /users/ HTTP/1.1" 200 971
"POST /users/logout/ HTTP/1.1" 302 0
"GET /users/login/ HTTP/1.1" 200 1916
- Broken pipe from ('127.0.0.1', 63535)
"POST /users/login/ HTTP/1.1" 302 0
"GET /users/ HTTP/1.1" 200 971
"GET /chipin/ HTTP/1.1" 200 1791
"GET /admin/ HTTP/1.1" 200 7448
"GET /admin/users/profile/ HTTP/1.1" 200 11486
"GET /admin/jsi18n/ HTTP/1.1" 200 3342
"GET /admin/users/profile/3/change/ HTTP/1.1" 200 11908
"GET /admin/jsi18n/ HTTP/1.1" 200 3342
"GET /admin/users/customuser/ HTTP/1.1" 200 13006
"GET /admin/jsi18n/ HTTP/1.1" 200 3342
"GET /admin/users/customuser/3/change/ HTTP/1.1" 200 22815
"GET /admin/jsi18n/ HTTP/1.1" 200 3342
"POST /admin/users/customuser/3/change/ HTTP/1.1" 200 22999
"GET /admin/jsi18n/ HTTP/1.1" 200 3342
"POST /admin/users/customuser/3/change/ HTTP/1.1" 302 0
"GET /admin/users/customuser/ HTTP/1.1" 200 13207
"GET /admin/jsi18n/ HTTP/1.1" 200 3342
"GET /admin/users/profile/ HTTP/1.1" 200 11486
"GET /admin/jsi18n/ HTTP/1.1" 200 3342
"POST /admin/users/profile/ HTTP/1.1" 200 7891
"POST /admin/users/profile/ HTTP/1.1" 302 0
"GET /admin/users/profile/ HTTP/1.1" 200 11193
"GET /admin/jsi18n/ HTTP/1.1" 200 3342
"GET /users/ HTTP/1.1" 200 965
"POST /users/logout/ HTTP/1.1" 302 0
"GET /users/login/ HTTP/1.1" 200 1916
"GET /users/register/ HTTP/1.1" 200 2762
"POST /users/register/ HTTP/1.1" 200 2956
"POST /users/register/ HTTP/1.1" 302 0
"GET /users/login/ HTTP/1.1" 200 1942
"POST /users/login/ HTTP/1.1" 302 0
"GET /users/ HTTP/1.1" 200 972
"GET /chipin/ HTTP/1.1" 200 1491
"GET /chipin/group/9/ HTTP/1.1" 200 1301
"GET /chipin/group/9/request-to-join/ HTTP/1.1" 302 0
"GET /chipin/group/9/ HTTP/1.1" 200 1456
"POST /users/logout/ HTTP/1.1" 302 0
"GET /users/login/ HTTP/1.1" 200 1916
"POST /users/login/ HTTP/1.1" 302 0
"GET /users/ HTTP/1.1" 200 976
"GET /chipin/ HTTP/1.1" 200 1599
"GET /chipin/group/9/ HTTP/1.1" 200 1674
"GET /chipin/group/9/request/2/vote/approve/ HTTP/1.1" 302 0
"GET /chipin/group/9/ HTTP/1.1" 200 1799
"GET /chipin/group/9/request/2/vote/approve/ HTTP/1.1" 302 0
"GET /chipin/group/9/ HTTP/1.1" 200 1799
"GET /chipin/group/9/request/2/vote/approve/ HTTP/1.1" 302 0
"GET /chipin/group/9/ HTTP/1.1" 200 1799
"GET /chipin/group/9/request/2/vote/approve/ HTTP/1.1" 302 0
"GET /chipin/group/9/ HTTP/1.1" 200 1799
"POST /users/logout/ HTTP/1.1" 302 0
"GET /users/login/ HTTP/1.1" 200 1916
"POST /users/login/ HTTP/1.1" 302 0
"GET /users/ HTTP/1.1" 200 976
"GET /chipin/ HTTP/1.1" 200 1599
"GET /chipin/group/9/delete/ HTTP/1.1" 302 0
"GET /chipin/ HTTP/1.1" 200 1565
"POST /users/logout/ HTTP/1.1" 302 0
"GET /users/login/ HTTP/1.1" 200 1916
"POST /users/login/ HTTP/1.1" 302 0
"GET /users/ HTTP/1.1" 200 971
"GET /admin/ HTTP/1.1" 200 6716
"GET /admin/auth/group/ HTTP/1.1" 200 8165
"GET /admin/jsi18n/ HTTP/1.1" 200 3342
"GET /admin/ HTTP/1.1" 200 6716
"GET /admin/users/profile/ HTTP/1.1" 200 11501
"GET /admin/jsi18n/ HTTP/1.1" 200 3342
"GET /admin/ HTTP/1.1" 200 6716
"GET /admin/users/customuser/ HTTP/1.1" 200 13587
"GET /admin/jsi18n/ HTTP/1.1" 200 3342
"POST /admin/users/customuser/ HTTP/1.1" 200 8247
"POST /admin/users/customuser/ HTTP/1.1" 302 0
"GET /admin/users/customuser/ HTTP/1.1" 200 13147
"GET /admin/jsi18n/ HTTP/1.1" 200 3342
"GET /admin/users/profile/ HTTP/1.1" 200 11501
"GET /admin/jsi18n/ HTTP/1.1" 200 3342
"GET /admin/users/profile/3/change/ HTTP/1.1" 200 11915
"GET /admin/jsi18n/ HTTP/1.1" 200 3342
"GET /admin/users/profile/ HTTP/1.1" 200 11501
"GET /admin/jsi18n/ HTTP/1.1" 200 3342
"GET /admin/users/profile/4/change/ HTTP/1.1" 200 11919
"GET /admin/jsi18n/ HTTP/1.1" 200 3342
"POST /admin/users/profile/4/change/ HTTP/1.1" 302 0
"GET /admin/users/profile/ HTTP/1.1" 200 11708
"GET /admin/jsi18n/ HTTP/1.1" 200 3342
"GET /admin/users/profile/3/change/ HTTP/1.1" 200 11915
"GET /admin/jsi18n/ HTTP/1.1" 200 3342
"GET /admin/users/customuser/ HTTP/1.1" 200 13013
"GET /admin/jsi18n/ HTTP/1.1" 200 3342
"GET /admin/users/customuser/3/change/ HTTP/1.1" 200 22831
"GET /admin/jsi18n/ HTTP/1.1" 200 3342
"GET /admin/ HTTP/1.1" 200 7400
"GET /static/admin/img/icon-deletelink.svg HTTP/1.1" 200 392
"GET /users/ HTTP/1.1" 200 971
"POST /users/logout/ HTTP/1.1" 302 0
"GET /users/login/ HTTP/1.1" 200 1916
"POST /users/login/ HTTP/1.1" 302 0
"GET /users/ HTTP/1.1" 200 971
"GET /chipin/ HTTP/1.1" 200 1417
"GET /chipin/create_group/ HTTP/1.1" 200 1278
"POST /chipin/create_group/ HTTP/1.1" 302 0
"GET /chipin/group/11/ HTTP/1.1" 200 1468
"POST /users/logout/ HTTP/1.1" 302 0
"GET /users/login/ HTTP/1.1" 200 1916
"POST /users/login/ HTTP/1.1" 302 0
"GET /users/ HTTP/1.1" 200 976
"GET /chipin/ HTTP/1.1" 200 1492
"GET /chipin/group/11/ HTTP/1.1" 200 1273
"GET /chipin/group/11/request-to-join/ HTTP/1.1" 302 0
"GET /chipin/group/11/ HTTP/1.1" 200 1428
"POST /users/logout/ HTTP/1.1" 302 0
"GET /users/login/ HTTP/1.1" 200 1916
"POST /users/login/ HTTP/1.1" 302 0
"GET /users/ HTTP/1.1" 200 971
"GET /chipin/ HTTP/1.1" 200 1599
"GET /chipin/group/11/ HTTP/1.1" 200 1559
"GET /chipin/group/11/request/3/vote/approve/ HTTP/1.1" 302 0
"GET /chipin/group/11/ HTTP/1.1" 200 1644
C:\Users\melie\ssa_project\chipin\views.py changed, reloading.
Watching for file changes with StatReloader
"POST /users/logout/ HTTP/1.1" 302 0
"GET /users/login/ HTTP/1.1" 200 1916
"POST /users/login/ HTTP/1.1" 302 0
"GET /users/ HTTP/1.1" 200 976
"GET /chipin/ HTTP/1.1" 200 1797
"GET /chipin/group/11/ HTTP/1.1" 200 1364
"POST /users/logout/ HTTP/1.1" 302 0
"GET /users/login/ HTTP/1.1" 200 1916
"POST /users/login/ HTTP/1.1" 302 0
"GET /users/ HTTP/1.1" 200 972
"GET /chipin/ HTTP/1.1" 200 1490
"GET /chipin/group/11/ HTTP/1.1" 200 1307
"GET /chipin/group/11/request-to-join/ HTTP/1.1" 302 0
"GET /chipin/group/11/ HTTP/1.1" 200 1462
"POST /users/logout/ HTTP/1.1" 302 0
"GET /users/login/ HTTP/1.1" 200 1916
"POST /users/login/ HTTP/1.1" 302 0
"GET /users/ HTTP/1.1" 200 976
"GET /chipin/ HTTP/1.1" 200 1797
"GET /chipin/group/11/ HTTP/1.1" 200 1611
"GET /chipin/group/11/request/4/vote/approve/ HTTP/1.1" 302 0
"GET /chipin/group/11/ HTTP/1.1" 200 1611
"GET /chipin/group/11/request/4/vote/approve/ HTTP/1.1" 302 0
"GET /chipin/group/11/ HTTP/1.1" 200 1736
"POST /users/logout/ HTTP/1.1" 302 0
"GET /users/login/ HTTP/1.1" 200 1916
"POST /users/login/ HTTP/1.1" 302 0
"GET /users/ HTTP/1.1" 200 971
"GET /chipin/ HTTP/1.1" 200 1599
"GET /chipin/group/11/ HTTP/1.1" 200 1673
"GET /chipin/group/11/request/4/vote/approve/ HTTP/1.1" 302 0
"GET /chipin/group/11/ HTTP/1.1" 200 1687
"POST /users/logout/ HTTP/1.1" 302 0
"GET /users/login/ HTTP/1.1" 200 1916
"POST /users/login/ HTTP/1.1" 302 0
"GET /users/ HTTP/1.1" 200 971
"GET /chipin/ HTTP/1.1" 200 1599
"GET /chipin/group/11/ HTTP/1.1" 200 1538
"GET /admin/ HTTP/1.1" 200 7400
"GET /admin/auth/group/ HTTP/1.1" 200 8165
"GET /admin/jsi18n/ HTTP/1.1" 200 3342
"GET /admin/auth/group/ HTTP/1.1" 200 8165
"GET /admin/jsi18n/ HTTP/1.1" 200 3342
"GET /admin/users/profile/ HTTP/1.1" 200 11502
"GET /admin/jsi18n/ HTTP/1.1" 200 3342
"GET /users/ HTTP/1.1" 200 971
"POST /users/logout/ HTTP/1.1" 302 0
"GET /users/login/ HTTP/1.1" 200 1916
"GET /users/register/ HTTP/1.1" 200 2762
"POST /users/register/ HTTP/1.1" 200 2937
"POST /users/register/ HTTP/1.1" 200 2937
"POST /users/register/ HTTP/1.1" 200 2937
Watching for file changes with StatReloader
"GET /users/ HTTP/1.1" 302 0
"GET /users/login/?next=/users/ HTTP/1.1" 200 1787
Not Found: /favicon.ico
"GET /favicon.ico HTTP/1.1" 404 2512
"POST /users/login/ HTTP/1.1" 302 0
"GET /users/ HTTP/1.1" 200 971
"GET /chipin/ HTTP/1.1" 200 1599
"GET /chipin/create_group/ HTTP/1.1" 200 1278
"POST /chipin/create_group/ HTTP/1.1" 200 1482
C:\Users\melie\ssa_project\chipin\models.py changed, reloading.
Watching for file changes with StatReloader
C:\Users\melie\ssa_project\chipin\forms.py changed, reloading.
Watching for file changes with StatReloader
C:\Users\melie\ssa_project\chipin\views.py changed, reloading.
Watching for file changes with StatReloader
C:\Users\melie\ssa_project\chipin\views.py changed, reloading.
Watching for file changes with StatReloader
C:\Users\melie\ssa_project\chipin\views.py changed, reloading.
Watching for file changes with StatReloader
C:\Users\melie\ssa_project\chipin\urls.py changed, reloading.
Watching for file changes with StatReloader
Watching for file changes with StatReloader
"GET /users/ HTTP/1.1" 302 0
"GET /users/login/?next=/users/ HTTP/1.1" 200 1787
"GET /static/chipin/styles.css HTTP/1.1" 304 0
"GET /static/chipin/logo_90.jpg HTTP/1.1" 304 0
Not Found: /favicon.ico
"GET /favicon.ico HTTP/1.1" 404 2512
"POST /users/login/ HTTP/1.1" 302 0
"GET /users/login/ HTTP/1.1" 200 1936
"GET /users/login/ HTTP/1.1" 200 2018
"POST /users/login/ HTTP/1.1" 302 0
"GET /users/ HTTP/1.1" 200 971
"GET /chipin/ HTTP/1.1" 200 1599
"GET /chipin/group/11/ HTTP/1.1" 200 2252
"POST /chipin/group/11/ HTTP/1.1" 302 0
"GET /chipin/group/11/ HTTP/1.1" 200 2647
"POST /chipin/group/11/ HTTP/1.1" 302 0
"GET /chipin/group/11/ HTTP/1.1" 200 3135
"POST /chipin/group/11/ HTTP/1.1" 302 0
"GET /chipin/group/11/ HTTP/1.1" 200 3602
